<?xml version="1.0" ?>
<!-- =================================================================================== -->
<!-- |    This document was autogenerated by xacro from nefive_description/urdf/nefive-simplified.urdf | -->
<!-- |    EDITING THIS FILE BY HAND IS NOT RECOMMENDED                                 | -->
<!-- =================================================================================== -->
<robot name="nefive">
  <material name="grey">
    <color rgba="0.5 0.5 0.5 1"/>
  </material>
  <material name="black">
    <color rgba="0 0 0 1"/>
  </material>
  <material name="Default-Material">
    <color rgba="1 1 1 1"/>
  </material>
  <link name="base_link"/>
  <link name="chassis">
    <visual>
      <geometry>
        <box size="0.104 0.147 0.068"/>
      </geometry>
      <material name="grey"/>
    </visual>
  </link>
  <joint name="base_link_chassis_joint" type="fixed">
    <parent link="base_link"/>
    <child link="chassis"/>
  </joint>
  <joint name="base_link_rear_right_wheel_joint" type="continuous">
    <origin xyz="-0.07 -0.078 -0.022"/>
    <parent link="chassis"/>
    <child link="rear_right_wheel"/>
    <axis xyz="0 1 0"/>
  </joint>
  <joint name="base_link_front_right_wheel_joint" type="continuous">
    <origin xyz="0.07 -0.078 -0.022"/>
    <parent link="chassis"/>
    <child link="front_right_wheel"/>
    <axis xyz="0 1 0"/>
  </joint>
  <joint name="base_link_front_left_wheel_joint" type="continuous">
    <origin xyz="0.07 0.078 -0.022"/>
    <parent link="chassis"/>
    <child link="front_left_wheel"/>
    <axis xyz="0 1 0"/>
  </joint>
  <joint name="base_link_rear_left_wheel_joint" type="continuous">
    <origin xyz="-0.07 0.078 -0.022"/>
    <parent link="chassis"/>
    <child link="rear_left_wheel"/>
    <axis xyz="0 1 0"/>
  </joint>
  <link name="rear_right_wheel">
    <visual>
      <origin rpy="-4.712389 0 0" xyz="0 -0.01 0"/>
      <geometry>
        <cylinder length="0.02" radius="0.025"/>
      </geometry>
      <material name="black"/>
    </visual>
  </link>
  <link name="front_right_wheel">
    <visual>
      <origin rpy="-4.712389 0 0" xyz="0 -0.01 0"/>
      <geometry>
        <cylinder length="0.02" radius="0.025"/>
      </geometry>
      <material name="black"/>
    </visual>
  </link>
  <link name="front_left_wheel">
    <visual>
      <origin rpy="-4.712389 0 0" xyz="0 0.01 0"/>
      <geometry>
        <cylinder length="0.02" radius="0.025"/>
      </geometry>
      <material name="black"/>
    </visual>
  </link>
  <link name="rear_left_wheel">
    <visual>
      <origin rpy="-4.712389 0 0" xyz="0 0.01 0"/>
      <geometry>
        <cylinder length="0.02" radius="0.025"/>
      </geometry>
      <material name="black"/>
    </visual>
  </link>
  <link name="lower_torso">
    <visual>
      <origin xyz="0 0 0.03"/>
      <geometry>
        <box size="0.015 0.06 0.06"/>
      </geometry>
      <material name="grey"/>
    </visual>
  </link>
  <link name="upper_torso">
    <visual>
      <origin xyz="0 0 0.03"/>
      <geometry>
        <box size="0.015 0.06 0.06"/>
      </geometry>
      <material name="grey"/>
    </visual>
  </link>
  <link name="chest_box">
    <visual>
      <origin xyz="0.0228 0 0.0564"/>
      <geometry>
        <box size="0.05 0.07 0.05"/>
      </geometry>
      <material name="grey"/>
    </visual>
  </link>
  <joint name="base_link_lower_torso_joint" type="fixed">
    <origin rpy="0 5.497787 0" xyz="-0.0241 0 0.0285"/>
    <parent link="chassis"/>
    <child link="lower_torso"/>
  </joint>
  <joint name="lower_torso_upper_torso_joint" type="fixed">
    <origin rpy="0 1.570451 0" xyz="0 0 0.06"/>
    <parent link="lower_torso"/>
    <child link="upper_torso"/>
  </joint>
  <joint name="upper_torso_chest_box_joint" type="fixed">
    <origin rpy="0 5.497787 0" xyz="0.0305 0 0.0269"/>
    <parent link="upper_torso"/>
    <child link="chest_box"/>
  </joint>
  <link name="head_pan">
    <visual>
      <geometry>
        <cylinder length="0.002" radius="0.02"/>
      </geometry>
      <material name="grey"/>
    </visual>
  </link>
  <link name="head_tilt">
    <visual>
      <geometry>
        <box size="0.04 0.04 0.001"/>
      </geometry>
      <material name="grey"/>
    </visual>
  </link>
  <link name="head">
    <visual>
      <origin xyz="-0.0039 0 0.0283"/>
      <geometry>
        <box size="0.107 0.11 0.054"/>
      </geometry>
      <material name="grey"/>
    </visual>
  </link>
  <link name="eyes">
    <visual>
      <geometry>
        <cylinder length="0" radius="0"/>
      </geometry>
      <material name="Default-Material"/>
    </visual>
  </link>
  <link name="left_eye_ring">
    <visual>
      <origin rpy="0 1.570451 0"/>
      <geometry>
        <cylinder length="0.002" radius="0.02"/>
      </geometry>
      <material name="Default-Material"/>
    </visual>
  </link>
  <link name="left_eye_inner">
    <visual>
      <origin rpy="0 1.570451 0" xyz="0.0006 0 0"/>
      <geometry>
        <cylinder length="0.002" radius="0.01"/>
      </geometry>
      <material name="black"/>
    </visual>
  </link>
  <link name="left_camera_pointcloud_frame">
  </link>
  <link name="right_eye_ring">
    <visual>
      <origin rpy="0 1.570451 0"/>
      <geometry>
        <cylinder length="0.002" radius="0.02"/>
      </geometry>
      <material name="Default-Material"/>
    </visual>
  </link>
  <link name="right_eye_inner">
    <visual>
      <origin rpy="0 1.570451 0" xyz="0.0006 0 0"/>
      <geometry>
        <cylinder length="0.002" radius="0.01"/>
      </geometry>
      <material name="black"/>
    </visual>
  </link>
  <link name="right_camera">
  </link>
  <joint name="chest_box_head_pan_joint" type="revolute">
    <origin xyz="0.025 0 0.0819"/>
    <parent link="chest_box"/>
    <child link="head_pan"/>
    <axis xyz="0 0 1"/>
    <limit effort="1000" lower="-0.785398" upper="0.785398" velocity="1000"/>
  </joint>
  <joint name="head_pan_head_tilt_joint" type="revolute">
    <origin xyz="0 0 0.035"/>
    <parent link="head_pan"/>
    <child link="head_tilt"/>
    <axis xyz="0 -1 0"/>
    <limit effort="1000" lower="-0.785398" upper="0.785398" velocity="1000"/>
  </joint>
  <joint name="head_tilt_head_joint" type="fixed">
    <parent link="head_tilt"/>
    <child link="head"/>
  </joint>
  <joint name="head_eyes_joint" type="fixed">
    <origin xyz="0.05 0 0.03"/>
    <parent link="head"/>
    <child link="eyes"/>
  </joint>
  <joint name="eyes_left_eye_ring_joint" type="fixed">
    <origin xyz="0 0.03 0"/>
    <parent link="eyes"/>
    <child link="left_eye_ring"/>
  </joint>
  <joint name="left_eye_ring_left_eye_inner_joint" type="fixed">
    <parent link="left_eye_ring"/>
    <child link="left_eye_inner"/>
  </joint>
  <joint name="left_eye_inner_left_camera_joint" type="fixed">
    <origin rpy="-1.57 0 -1.57"/>
    <parent link="left_eye_inner"/>
    <child link="left_camera_pointcloud_frame"/>
  </joint>
  <joint name="eyes_right_eye_ring_joint" type="fixed">
    <origin xyz="0 -0.03 0"/>
    <parent link="eyes"/>
    <child link="right_eye_ring"/>
  </joint>
  <joint name="right_eye_ring_right_eye_inner_joint" type="fixed">
    <parent link="right_eye_ring"/>
    <child link="right_eye_inner"/>
  </joint>
  <joint name="right_eye_inner_right_camera_joint" type="fixed">
    <parent link="right_eye_inner"/>
    <child link="right_camera"/>
  </joint>
  <link name="arms">
  </link>
  <link name="right_arm">
  </link>
  <link name="right_shoulder_tilt">
    <visual>
      <origin rpy="0 1.570451 0"/>
      <geometry>
        <cylinder length="0.02" radius="0.0005"/>
      </geometry>
      <material name="grey"/>
    </visual>
  </link>
  <link name="right_shoulder_pan">
    <visual>
      <origin rpy="-4.712389 0 0" xyz="0 -0.002 0"/>
      <geometry>
        <cylinder length="0.004" radius="0.0005"/>
      </geometry>
      <material name="grey"/>
    </visual>
  </link>
  <link name="right_shoulder_rotate">
    <visual>
      <origin rpy="-4.712389 0 -4.712389" xyz="0.0001 -0.002 0"/>
      <geometry>
        <cylinder length="0.004" radius="0.0005"/>
      </geometry>
      <material name="grey"/>
    </visual>
    <visual>
      <origin rpy="0 1.570451 0" xyz="0.031 -0.002 0"/>
      <geometry>
        <cylinder length="-0.06" radius="0.005"/>
      </geometry>
      <material name="grey"/>
    </visual>
  </link>
  <link name="right_elbow">
    <visual>
      <origin rpy="0 1.570451 0"/>
      <geometry>
        <cylinder length="0.02" radius="0.0005"/>
      </geometry>
      <material name="grey"/>
    </visual>
  </link>
  <link name="right_forearm">
    <visual>
      <origin rpy="0 1.570451 0" xyz="0.035 -0.0025 0"/>
      <geometry>
        <cylinder length="0.07" radius="0.005"/>
      </geometry>
      <material name="grey"/>
    </visual>
  </link>
  <link name="right_wrist_roll">
    <visual>
      <geometry>
        <cylinder length="0.01" radius="0.0005"/>
      </geometry>
      <material name="grey"/>
    </visual>
  </link>
  <link name="right_wrist_tilt">
    <visual>
      <geometry>
        <cylinder length="0.01" radius="0.0005"/>
      </geometry>
      <material name="grey"/>
    </visual>
  </link>
  <link name="right_wrist_pan">
    <visual>
      <geometry>
        <cylinder length="0.01" radius="0.0005"/>
      </geometry>
      <material name="grey"/>
    </visual>
  </link>
  <link name="right_hand">
    <visual>
      <geometry>
        <box size="0.02 0.02 0.02"/>
      </geometry>
      <material name="grey"/>
    </visual>
  </link>
  <link name="left_arm">
  </link>
  <link name="left_shoulder_tilt">
    <visual>
      <origin rpy="0 1.570451 0"/>
      <geometry>
        <cylinder length="0.02" radius="0.0005"/>
      </geometry>
      <material name="grey"/>
    </visual>
  </link>
  <link name="left_shoulder_pan">
    <visual>
      <origin rpy="-4.712389 0 0" xyz="0 -0.002 0"/>
      <geometry>
        <cylinder length="0.004" radius="0.0005"/>
      </geometry>
      <material name="grey"/>
    </visual>
  </link>
  <link name="left_shoulder_rotate">
    <visual>
      <origin rpy="-4.712389 0 -4.712389" xyz="0.0001 -0.002 0"/>
      <geometry>
        <cylinder length="0.004" radius="0.0005"/>
      </geometry>
      <material name="grey"/>
    </visual>
    <visual>
      <origin rpy="0 1.570451 0" xyz="0.031 -0.002 0"/>
      <geometry>
        <cylinder length="-0.06" radius="0.005"/>
      </geometry>
      <material name="grey"/>
    </visual>
  </link>
  <link name="left_elbow">
    <visual>
      <origin rpy="0 1.570451 0"/>
      <geometry>
        <cylinder length="0.02" radius="0.0005"/>
      </geometry>
      <material name="grey"/>
    </visual>
  </link>
  <link name="left_forearm">
    <visual>
      <origin rpy="0 1.570451 0" xyz="0.035 -0.0025 0"/>
      <geometry>
        <cylinder length="0.07" radius="0.005"/>
      </geometry>
      <material name="grey"/>
    </visual>
  </link>
  <link name="left_wrist_roll">
    <visual>
      <geometry>
        <cylinder length="0.01" radius="0.0005"/>
      </geometry>
      <material name="grey"/>
    </visual>
  </link>
  <link name="left_wrist_tilt">
    <visual>
      <geometry>
        <cylinder length="0.01" radius="0.0005"/>
      </geometry>
      <material name="grey"/>
    </visual>
  </link>
  <link name="left_wrist_pan">
    <visual>
      <geometry>
        <cylinder length="0.01" radius="0.0005"/>
      </geometry>
      <material name="grey"/>
    </visual>
  </link>
  <link name="left_hand">
    <visual>
      <geometry>
        <box size="0.02 0.02 0.02"/>
      </geometry>
      <material name="grey"/>
    </visual>
  </link>
  <joint name="chest_box_arms_joint" type="fixed">
    <origin xyz="0.025 0 0.075"/>
    <parent link="chest_box"/>
    <child link="arms"/>
  </joint>
  <joint name="arms_right_arm_joint" type="fixed">
    <origin xyz="0 -0.06 0"/>
    <parent link="arms"/>
    <child link="right_arm"/>
  </joint>
  <joint name="right_arm_right_shoulder_tilt_joint" type="revolute">
    <origin rpy="0 0.785398 0"/>
    <parent link="right_arm"/>
    <child link="right_shoulder_tilt"/>
    <axis xyz="1 0 0"/>
    <limit effort="1000" lower="-0.610865" upper="0.436332" velocity="1000"/>
  </joint>
  <joint name="right_shoulder_tilt_right_shoulder_pan_joint" type="revolute">
    <origin rpy="0 0.785398 0" xyz="0 -0.001 0"/>
    <parent link="right_shoulder_tilt"/>
    <child link="right_shoulder_pan"/>
    <axis xyz="0 -1 0"/>
    <limit effort="1000" lower="-1.570796" upper="1.570796" velocity="1000"/>
  </joint>
  <joint name="right_shoulder_pan_right_shoulder_rotate_joint" type="revolute">
    <origin rpy="0 0.785398 0" xyz="0 -0.0048 0"/>
    <parent link="right_shoulder_pan"/>
    <child link="right_shoulder_rotate"/>
    <axis xyz="1 0 0"/>
    <limit effort="1000" lower="-1.570796" upper="1.570796" velocity="1000"/>
  </joint>
  <joint name="right_shoulder_rotate_right_elbow_joint" type="revolute">
    <origin xyz="0.075 0 0"/>
    <parent link="right_shoulder_rotate"/>
    <child link="right_elbow"/>
    <axis xyz="0 -1 0"/>
    <limit effort="1000" lower="0" upper="0" velocity="1000"/>
  </joint>
  <joint name="right_elbow_right_forearm_joint" type="revolute">
    <origin rpy="-3.141593 5.497787 -3.141593" xyz="0.01 0 0.0025"/>
    <parent link="right_elbow"/>
    <child link="right_forearm"/>
    <axis xyz="0 -1 0"/>
    <limit effort="1000" lower="0" upper="0" velocity="1000"/>
  </joint>
  <joint name="right_forearm_right_wrist_roll_joint" type="revolute">
    <origin rpy="0 4.712734 0" xyz="0.0683 -0.0025 0"/>
    <parent link="right_forearm"/>
    <child link="right_wrist_roll"/>
    <axis xyz="0 0 1"/>
    <limit effort="1000" lower="-1.570796" upper="1.570796" velocity="1000"/>
  </joint>
  <joint name="right_wrist_roll_right_wrist_tilt_joint" type="revolute">
    <origin rpy="0 1.570796 -4.712389" xyz="0 0 -0.00636"/>
    <parent link="right_wrist_roll"/>
    <child link="right_wrist_tilt"/>
    <axis xyz="0 0 1"/>
    <limit effort="1000" lower="-0.785398" upper="0.785398" velocity="1000"/>
  </joint>
  <joint name="right_wrist_tilt_right_wrist_pan_joint" type="revolute">
    <origin rpy="-4.712389 0 0" xyz="0.002 0 0"/>
    <parent link="right_wrist_tilt"/>
    <child link="right_wrist_pan"/>
    <axis xyz="0 0 1"/>
    <limit effort="1000" lower="-0.785398" upper="0.785398" velocity="1000"/>
  </joint>
  <joint name="right_wrist_pan_right_hand_joint" type="fixed">
    <origin xyz="0.012 0 0"/>
    <parent link="right_wrist_pan"/>
    <child link="right_hand"/>
  </joint>
  <joint name="arms_left_arm_joint" type="fixed">
    <origin rpy="0 0 -3.141593" xyz="0 0.06 0"/>
    <parent link="arms"/>
    <child link="left_arm"/>
  </joint>
  <joint name="left_arm_left_shoulder_tilt_joint" type="revolute">
    <origin rpy="0 5.497787 0"/>
    <parent link="left_arm"/>
    <child link="left_shoulder_tilt"/>
    <axis xyz="1 0 0"/>
    <limit effort="1000" lower="-0.610865" upper="0.436332" velocity="1000"/>
  </joint>
  <joint name="left_shoulder_tilt_left_shoulder_pan_joint" type="revolute">
    <origin rpy="-3.141593 0.785398 -3.141593" xyz="0 -0.001 0"/>
    <parent link="left_shoulder_tilt"/>
    <child link="left_shoulder_pan"/>
    <axis xyz="0 -1 0"/>
    <limit effort="1000" lower="-1.570796" upper="1.570796" velocity="1000"/>
  </joint>
  <joint name="left_shoulder_pan_left_shoulder_rotate_joint" type="revolute">
    <origin rpy="0 5.497787 0" xyz="0 -0.0048 0"/>
    <parent link="left_shoulder_pan"/>
    <child link="left_shoulder_rotate"/>
    <axis xyz="1 0 0"/>
    <limit effort="1000" lower="-1.570796" upper="1.570796" velocity="1000"/>
  </joint>
  <joint name="left_shoulder_rotate_left_elbow_joint" type="revolute">
    <origin xyz="0.075 0 0"/>
    <parent link="left_shoulder_rotate"/>
    <child link="left_elbow"/>
    <axis xyz="0 -1 0"/>
    <limit effort="1000" lower="0" upper="0" velocity="1000"/>
  </joint>
  <joint name="left_elbow_left_forearm_joint" type="revolute">
    <origin rpy="-3.141593 0.785398 -3.141593" xyz="0.01 0 0.0025"/>
    <parent link="left_elbow"/>
    <child link="left_forearm"/>
    <axis xyz="0 -1 0"/>
    <limit effort="1000" lower="0" upper="0" velocity="1000"/>
  </joint>
  <joint name="left_forearm_left_wrist_roll_joint" type="revolute">
    <origin rpy="0 4.712734 0" xyz="0.0683 -0.0025 0"/>
    <parent link="left_forearm"/>
    <child link="left_wrist_roll"/>
    <axis xyz="0 0 1"/>
    <limit effort="1000" lower="-1.570796" upper="1.570796" velocity="1000"/>
  </joint>
  <joint name="left_wrist_roll_left_wrist_tilt_joint" type="revolute">
    <origin rpy="0 1.570796 -4.712389" xyz="0 0 -0.00636"/>
    <parent link="left_wrist_roll"/>
    <child link="left_wrist_tilt"/>
    <axis xyz="0 0 1"/>
    <limit effort="1000" lower="-0.785398" upper="0.785398" velocity="1000"/>
  </joint>
  <joint name="left_wrist_tilt_left_wrist_pan_joint" type="revolute">
    <origin rpy="-4.712389 0 0" xyz="0.002 0 0"/>
    <parent link="left_wrist_tilt"/>
    <child link="left_wrist_pan"/>
    <axis xyz="0 0 1"/>
    <limit effort="1000" lower="-0.785398" upper="0.785398" velocity="1000"/>
  </joint>
  <joint name="left_wrist_pan_left_hand_joint" type="fixed">
    <origin xyz="0.012 0 0"/>
    <parent link="left_wrist_pan"/>
    <child link="left_hand"/>
  </joint>
</robot>
