<?xml version="1.0"?>
<robot xmlns:xacro="http://www.ros.org/wiki/xacro">
  
<link name="arms" />
  
<xacro:macro name="arm" params="prefix reflect">
  <link name="${prefix}_arm" />

  <link name="${prefix}_shoulder_flappy">
    <visual>
      <origin rpy="${pi/2} 0 0" xyz="0 0 0" />
      <geometry>
        <cylinder length="0.02" radius="0.0005" />
      </geometry>
      <material name="grey" />
    </visual>
  </link>

  <link name="${prefix}_shoulder_foreaft">
    <visual>
      <origin rpy="0 ${pi/2} 0" xyz="0 0 0" />
      <geometry>
        <cylinder length="0.004" radius="0.0005" />
      </geometry>
      <material name="grey" />
    </visual>
  </link>

  <link name="${prefix}_shoulder_rotate">
    <visual>
      <origin rpy="0 0 0" xyz="0 0 0" />
      <geometry>
        <cylinder length="0.004" radius="0.0005" />
      </geometry>
      <material name="grey" />
    </visual>
    <visual>
      <origin rpy="0 0 0" xyz="0 0 0.03" />
      <geometry>
        <cylinder length="0.06" radius="0.005" />
      </geometry>
      <material name="grey" />
    </visual>
  </link>

  <link name="${prefix}_elbow">
    <visual>
      <origin rpy="${pi/2} 0 0" xyz="0 0 0" />
      <geometry>
        <cylinder length="0.004" radius="0.0005" />
      </geometry>
      <material name="grey" />
    </visual>
    <visual>
      <origin rpy="0 ${pi/2} 0" xyz="0.021 0 0" />
      <geometry>
        <cylinder length="0.042" radius="0.005" />
      </geometry>
      <material name="grey" />
    </visual>
  </link>

  <link name="${prefix}_wrist_rotate">
    <visual>
      <origin rpy="0 ${pi/2} 0" xyz="0 0 0" />
      <geometry>
        <cylinder length="0.004" radius="0.0005" />
      </geometry>
      <material name="grey" />
    </visual>
    <visual>
      <origin rpy="0 ${pi/2} 0" xyz="0.017 0 0" />
      <geometry>
        <cylinder length="0.034" radius="0.005" />
      </geometry>
      <material name="grey" />
    </visual>
  </link>

  <link name="${prefix}_wrist_pan">
    <visual>
      <geometry>
        <cylinder length="0.01" radius="0.0005" />
      </geometry>
      <material name="grey" />
    </visual>
    
    <visual>
      <origin rpy="0 ${pi/2} 0" xyz="0.016 0 0" />
      <geometry>
        <cylinder length="0.032" radius="0.005" />
      </geometry>
      <material name="grey" />
    </visual>
  </link>

  <link name="${prefix}_wrist_tilt">
    <visual>
      <geometry>
        <cylinder length="0.01" radius="0.0005" />
      </geometry>
      <material name="grey" />
    </visual>
  </link>

  <link name="${prefix}_hand">
    <visual>
      <geometry>
        <box size="0.02 0.02 0.02" />
      </geometry>
      <material name="grey" />
    </visual>
  </link>

  <joint name="arms_${prefix}_arm" type="fixed">
    <origin rpy="0 0 0" xyz="${reflect * -0.075} 0 0" />
    <parent link="arms" />
    <child link="${prefix}_arm" />
  </joint>

  <joint name="${prefix}_arm_${prefix}_shoulder_flappy_joint" type="revolute">
    <origin rpy="0 0 0" xyz="0 0 0" />
    <parent link="${prefix}_arm" />
    <child link="${prefix}_shoulder_flappy" />
    <axis xyz="0 -1 0" />
    <limit effort="10" lower="-${pi/2}" upper="${pi/2}" velocity="1000" />
  </joint>

  <joint name="${prefix}_shoulder_flappy_${prefix}_shoulder_foreaft_joint" type="revolute">
    <origin rpy="0 0 0" xyz="${reflect * -0.025} 0 0" />
    <parent link="${prefix}_shoulder_flappy" />
    <child link="${prefix}_shoulder_foreaft" />
    <axis xyz="${reflect} 0 0" />
    <limit effort="10" lower="-${pi/2}" upper="${pi/2}" velocity="1000" />
  </joint>

  <joint name="${prefix}_shoulder_foreaft_${prefix}_shoulder_rotate_joint" type="revolute">
    <origin rpy="0 0 -${pi/2}" xyz="0 0 -0.067" />
    <parent link="${prefix}_shoulder_foreaft" />
    <child link="${prefix}_shoulder_rotate" />
    <axis xyz="0 0 -1" />
    <limit effort="10" lower="-${pi/2}" upper="${pi/2}" velocity="1000" />
  </joint>

  <joint name="${prefix}_shoulder_rotate_${prefix}_elbow_joint" type="revolute">
    <origin rpy="0 ${pi} 0" xyz="0 0 0" />
    <parent link="${prefix}_shoulder_rotate" />
    <child link="${prefix}_elbow" />
    <axis xyz="0 ${reflect} 0" />
    <limit effort="10" lower="-${pi/2}" upper="${pi/2}" velocity="1000" />
  </joint>

  <joint name="${prefix}_forearm_${prefix}_wrist_rotate_joint" type="revolute">
    <origin rpy="0 0 0" xyz="0.042 0 0" />
    <parent link="${prefix}_elbow" />
    <child link="${prefix}_wrist_rotate" />
    <axis xyz="1 0 0" />
    <limit effort="10" lower="-${pi/2}" upper="${pi/2}" velocity="1000" />
  </joint>

  <joint name="${prefix}_wrist_rotate_${prefix}_wrist_pan_joint" type="revolute">
    <origin rpy="0 0 0" xyz="0.034 0 0" />
    <parent link="${prefix}_wrist_rotate" />
    <child link="${prefix}_wrist_pan" />
    <axis xyz="0 0 1" />
    <limit effort="10" lower="-${pi/2}" upper="${pi/2}" velocity="1000" />
  </joint>

  <joint name="${prefix}_wrist_pan_${prefix}_wrist_tilt_joint" type="revolute">
    <origin rpy="1.57 0 0" xyz="0.036 0 0" />
    <parent link="${prefix}_wrist_pan" />
    <child link="${prefix}_wrist_tilt" />
    <axis xyz="0 0 ${reflect}" />
    <limit effort="10" lower="-${pi/2}" upper="${pi/2}" velocity="1000" />
  </joint>

  <joint name="${prefix}_wrist_tilt_${prefix}_hand_joint" type="fixed">
    <origin xyz="0.012 0 0" />
    <parent link="${prefix}_wrist_tilt" />
    <child link="${prefix}_hand" />
  </joint> 
</xacro:macro>

<xacro:arm prefix="left" reflect="1"/>  
<xacro:arm prefix="right" reflect="-1"/>  

</robot>


