<?xml version="1.0"?>
<robot xmlns:xacro="http://www.ros.org/wiki/xacro">
  <link name="left_arm" />

  <link name="left_shoulder_flappy">
    <visual>
      <origin rpy="1.570451 0 0" xyz="0 0 0" />
      <geometry>
        <cylinder length="0.02" radius="0.0005" />
      </geometry>
      <material name="grey" />
    </visual>
  </link>

  <link name="left_shoulder_foreaft">
    <visual>
      <origin rpy="0 1.570451 0" xyz="0 0 0" />
      <geometry>
        <cylinder length="0.004" radius="0.0005" />
      </geometry>
      <material name="grey" />
    </visual>
  </link>

  <link name="left_shoulder_rotate">
    <visual>
      <origin rpy="0 0 0" xyz="0 0 0" />
      <geometry>
        <cylinder length="0.004" radius="0.0005" />
      </geometry>
      <material name="grey" />
    </visual>
    <visual>
      <origin rpy="0 0 0" xyz="0 0 0.03" />
      <geometry>
        <cylinder length="0.06" radius="0.005" />
      </geometry>
      <material name="grey" />
    </visual>
  </link>

  <link name="left_elbow">
    <visual>
      <origin rpy="1.570451 0 0" xyz="0 0 0" />
      <geometry>
        <cylinder length="0.004" radius="0.0005" />
      </geometry>
      <material name="grey" />
    </visual>
    <visual>
      <origin rpy="0 1.570451 0" xyz="0.021 0 0" />
      <geometry>
        <cylinder length="0.042" radius="0.005" />
      </geometry>
      <material name="grey" />
    </visual>
  </link>

  <link name="left_wrist_rotate">
    <visual>
      <origin rpy="0 1.570451 0" xyz="0 0 0" />
      <geometry>
        <cylinder length="0.004" radius="0.0005" />
      </geometry>
      <material name="grey" />
    </visual>
  </link>

  <link name="left_wrist_flappy">
    <visual>
      <geometry>
        <cylinder length="0.01" radius="0.0005" />
      </geometry>
      <material name="grey" />
    </visual>
  </link>
  <link name="left_wrist_pan">
    <visual>
      <geometry>
        <cylinder length="0.01" radius="0.0005" />
      </geometry>
      <material name="grey" />
    </visual>
  </link>
  <link name="left_hand">
    <visual>
      <geometry>
        <box size="0.02 0.02 0.02" />
      </geometry>
      <material name="grey" />
    </visual>
  </link>

  <joint name="left_arm_left_shoulder_flappy_joint" type="revolute">
    <origin rpy="0 0 0" xyz="0 0 0" />
    <parent link="left_arm" />
    <child link="left_shoulder_flappy" />
    <axis xyz="0 1 0" />
    <limit effort="1000" lower="-1.570796" upper="1.570796" velocity="1000" />
  </joint>

  <joint name="left_shoulder_flappy_left_shoulder_foreaft_joint" type="revolute">
    <origin rpy="0 0 0" xyz="-0.025 0 0" />
    <parent link="left_shoulder_flappy" />
    <child link="left_shoulder_foreaft" />
    <axis xyz="1 0 0" />
    <limit effort="1000" lower="-1.570796" upper="1.570796" velocity="1000" />
  </joint>

  <joint name="left_shoulder_foreaft_left_shoulder_rotate_joint" type="revolute">
    <origin rpy="0 0 -1.570451" xyz="0 0 -0.067" />
    <parent link="left_shoulder_foreaft" />
    <child link="left_shoulder_rotate" />
    <axis xyz="0 0 1" />
    <limit effort="1000" lower="-1.570796" upper="1.570796" velocity="1000" />
  </joint>

  <joint name="left_shoulder_rotate_left_elbow_joint" type="revolute">
    <origin rpy="0 3.14 0" xyz="0 0 0" />
    <parent link="left_shoulder_rotate" />
    <child link="left_elbow" />
    <axis xyz="0 1 0" />
    <limit effort="1000" lower="-1" upper="1" velocity="1000" />
  </joint>

  <joint name="left_forearm_left_wrist_rotate_joint" type="revolute">
    <origin rpy="0 0 0" xyz="0.042 0 0" />
    <parent link="left_elbow" />
    <child link="left_wrist_rotate" />
    <axis xyz="1 0 0" />
    <limit effort="1000" lower="-1.570796" upper="1.570796" velocity="1000" />
  </joint>

  <joint name="left_wrist_rotate_left_wrist_flappy_joint" type="revolute">
    <origin rpy="0 1.570796 -4.712389" xyz="0 0 -0.00636" />
    <parent link="left_wrist_rotate" />
    <child link="left_wrist_flappy" />
    <axis xyz="0 0 1" />
    <limit effort="1000" lower="-0.785398" upper="0.785398" velocity="1000" />
  </joint>

  <joint name="left_wrist_flappy_left_wrist_pan_joint" type="revolute">
    <origin rpy="-4.712389 0 0" xyz="0.002 0 0" />
    <parent link="left_wrist_flappy" />
    <child link="left_wrist_pan" />
    <axis xyz="0 0 1" />
    <limit effort="1000" lower="-0.785398" upper="0.785398" velocity="1000" />
  </joint>

  <joint name="left_wrist_pan_left_hand_joint" type="fixed">
    <origin xyz="0.012 0 0" />
    <parent link="left_wrist_pan" />
    <child link="left_hand" />
  </joint> 
  
  </robot>


