<?xml version="1.0"?>
<robot xmlns:xacro="http://www.ros.org/wiki/xacro" >

<link name="arms">
  </link>

  <link name="right_arm">
  </link>
    <link name="right_shoulder_tilt">
      <visual>
        <origin rpy="0 1.570451 0" />
        <geometry>
          <cylinder length="0.02" radius="0.0005" />
        </geometry>
        <material name="grey" />
      </visual>
    </link>
    <link name="right_shoulder_pan">
      <visual>
        <origin rpy="-4.712389 0 0" xyz="0 -0.002 0" />
        <geometry>
          <cylinder length="0.004" radius="0.0005" />
        </geometry>
        <material name="grey" />
      </visual>
    </link>
    <link name="right_shoulder_rotate">
      <visual>
        <origin rpy="-4.712389 0 -4.712389" xyz="0.0001 -0.002 0" />
        <geometry>
          <cylinder length="0.004" radius="0.0005" />
        </geometry>
        <material name="grey" />
      </visual>
      <visual>
        <origin rpy="0 1.570451 0" xyz="0.031 -0.002 0" />
        <geometry>
          <cylinder length="-0.06" radius="0.005" />
        </geometry>
        <material name="grey" />
      </visual>
    </link>
    <link name="right_elbow">
      <visual>
        <origin rpy="0 1.570451 0" />
        <geometry>
          <cylinder length="0.02" radius="0.0005" />
        </geometry>
        <material name="grey" />
      </visual>
    </link>
    <link name="right_forearm">
      <visual>
        <origin rpy="0 1.570451 0" xyz="0.035 -0.0025 0" />
        <geometry>
          <cylinder length="0.07" radius="0.005" />
        </geometry>
        <material name="grey" />
      </visual>
    </link>
    <link name="right_wrist_roll">
      <visual>
        <geometry>
          <cylinder length="0.01" radius="0.0005" />
        </geometry>
        <material name="grey" />
      </visual>
    </link>
    <link name="right_wrist_tilt">
      <visual>
        <geometry>
          <cylinder length="0.01" radius="0.0005" />
        </geometry>
        <material name="grey" />
      </visual>
    </link>
    <link name="right_wrist_pan">
      <visual>
        <geometry>
          <cylinder length="0.01" radius="0.0005" />
        </geometry>
        <material name="grey" />
      </visual>
    </link>
    <link name="right_hand">
      <visual>
        <geometry>
          <box size="0.02 0.02 0.02" />
        </geometry>
        <material name="grey" />
      </visual>
    </link>
  
  <link name="left_arm">
  </link>
  <link name="left_shoulder_tilt">
    <visual>
      <origin rpy="0 1.570451 0" />
      <geometry>
        <cylinder length="0.02" radius="0.0005" />
      </geometry>
      <material name="grey" />
    </visual>
  </link>
  <link name="left_shoulder_pan">
    <visual>
      <origin rpy="-4.712389 0 0" xyz="0 -0.002 0" />
      <geometry>
        <cylinder length="0.004" radius="0.0005" />
      </geometry>
      <material name="grey" />
    </visual>
  </link>
  <link name="left_shoulder_rotate">
    <visual>
      <origin rpy="-4.712389 0 -4.712389" xyz="0.0001 -0.002 0" />
      <geometry>
        <cylinder length="0.004" radius="0.0005" />
      </geometry>
      <material name="grey" />
    </visual>
    <visual>
      <origin rpy="0 1.570451 0" xyz="0.031 -0.002 0" />
      <geometry>
        <cylinder length="-0.06" radius="0.005" />
      </geometry>
      <material name="grey" />
    </visual>
  </link>
  <link name="left_elbow">
    <visual>
      <origin rpy="0 1.570451 0" />
      <geometry>
        <cylinder length="0.02" radius="0.0005" />
      </geometry>
      <material name="grey" />
    </visual>
  </link>
  <link name="left_forearm">
    <visual>
      <origin rpy="0 1.570451 0" xyz="0.035 -0.0025 0" />
      <geometry>
        <cylinder length="0.07" radius="0.005" />
      </geometry>
      <material name="grey" />
    </visual>
  </link>
  <link name="left_wrist_roll">
    <visual>
      <geometry>
        <cylinder length="0.01" radius="0.0005" />
      </geometry>
      <material name="grey" />
    </visual>
  </link>
  <link name="left_wrist_tilt">
    <visual>
      <geometry>
        <cylinder length="0.01" radius="0.0005" />
      </geometry>
      <material name="grey" />
    </visual>
  </link>
  <link name="left_wrist_pan">
    <visual>
      <geometry>
        <cylinder length="0.01" radius="0.0005" />
      </geometry>
      <material name="grey" />
    </visual>
  </link>
  <link name="left_hand">
    <visual>
      <geometry>
        <box size="0.02 0.02 0.02" />
      </geometry>
      <material name="grey" />
    </visual>
  </link>

  <joint name="arms_right_arm_joint" type="fixed">
    <origin xyz="0 -0.06 0" />
    <parent link="arms" />
    <child link="right_arm" />
  </joint>
  <joint name="right_arm_right_shoulder_tilt_joint" type="revolute">
    <origin rpy="0 0.785398 0" />
    <parent link="right_arm" />
    <child link="right_shoulder_tilt" />
    <axis xyz="1 0 0" />
    <limit lower="-0.610865" upper="0.436332" effort="1000" velocity="1000" />
  </joint>
  <joint name="right_shoulder_tilt_right_shoulder_pan_joint" type="revolute">
    <origin rpy="0 0.785398 0" xyz="0 -0.001 0" />
    <parent link="right_shoulder_tilt" />
    <child link="right_shoulder_pan" />
    <axis xyz="0 -1 0" />
    <limit lower="-1.570796" upper="1.570796" effort="1000" velocity="1000" />
  </joint>
  <joint name="right_shoulder_pan_right_shoulder_rotate_joint" type="revolute">
    <origin rpy="0 0.785398 0" xyz="0 -0.0048 0" />
    <parent link="right_shoulder_pan" />
    <child link="right_shoulder_rotate" />
    <axis xyz="1 0 0" />
    <limit lower="-1.570796" upper="1.570796" effort="1000" velocity="1000" />
  </joint>
  <joint name="right_shoulder_rotate_right_elbow_joint" type="revolute">
    <origin xyz="0.075 0 0" />
    <parent link="right_shoulder_rotate" />
    <child link="right_elbow" />
    <axis xyz="0 -1 0" />
    <limit lower="0" upper="0" effort="1000" velocity="1000" />
  </joint>
  <joint name="right_elbow_right_forearm_joint" type="revolute">
    <origin rpy="-3.141593 5.497787 -3.141593" xyz="0.01 0 0.0025" />
    <parent link="right_elbow" />
    <child link="right_forearm" />
    <axis xyz="0 -1 0" />
    <limit lower="0" upper="0" effort="1000" velocity="1000" />
  </joint>
  <joint name="right_forearm_right_wrist_roll_joint" type="revolute">
    <origin rpy="0 4.712734 0" xyz="0.0683 -0.0025 0" />
    <parent link="right_forearm" />
    <child link="right_wrist_roll" />
    <axis xyz="0 0 1" />
    <limit lower="-1.570796" upper="1.570796" effort="1000" velocity="1000" />
  </joint>
  <joint name="right_wrist_roll_right_wrist_tilt_joint" type="revolute">
    <origin rpy="0 1.570796 -4.712389" xyz="0 0 -0.00636" />
    <parent link="right_wrist_roll" />
    <child link="right_wrist_tilt" />
    <axis xyz="0 0 1" />
    <limit lower="-0.785398" upper="0.785398" effort="1000" velocity="1000" />
  </joint>
  <joint name="right_wrist_tilt_right_wrist_pan_joint" type="revolute">
    <origin rpy="-4.712389 0 0" xyz="0.002 0 0" />
    <parent link="right_wrist_tilt" />
    <child link="right_wrist_pan" />
    <axis xyz="0 0 1" />
    <limit lower="-0.785398" upper="0.785398" effort="1000" velocity="1000" />
  </joint>
  <joint name="right_wrist_pan_right_hand_joint" type="fixed">
    <origin xyz="0.012 0 0" />
    <parent link="right_wrist_pan" />
    <child link="right_hand" />
  </joint>
  <joint name="arms_left_arm_joint" type="fixed">
    <origin rpy="0 0 -3.141593" xyz="0 0.06 0" />
    <parent link="arms" />
    <child link="left_arm" />
  </joint>
  <joint name="left_arm_left_shoulder_tilt_joint" type="revolute">
    <origin rpy="0 5.497787 0" />
    <parent link="left_arm" />
    <child link="left_shoulder_tilt" />
    <axis xyz="1 0 0" />
    <limit lower="-0.610865" upper="0.436332" effort="1000" velocity="1000" />
  </joint>
  <joint name="left_shoulder_tilt_left_shoulder_pan_joint" type="revolute">
    <origin rpy="-3.141593 0.785398 -3.141593" xyz="0 -0.001 0" />
    <parent link="left_shoulder_tilt" />
    <child link="left_shoulder_pan" />
    <axis xyz="0 -1 0" />
    <limit lower="-1.570796" upper="1.570796" effort="1000" velocity="1000" />
  </joint>
  <joint name="left_shoulder_pan_left_shoulder_rotate_joint" type="revolute">
    <origin rpy="0 5.497787 0" xyz="0 -0.0048 0" />
    <parent link="left_shoulder_pan" />
    <child link="left_shoulder_rotate" />
    <axis xyz="1 0 0" />
    <limit lower="-1.570796" upper="1.570796" effort="1000" velocity="1000" />
  </joint>
  <joint name="left_shoulder_rotate_left_elbow_joint" type="revolute">
    <origin xyz="0.075 0 0" />
    <parent link="left_shoulder_rotate" />
    <child link="left_elbow" />
    <axis xyz="0 -1 0" />
    <limit lower="0" upper="0" effort="1000" velocity="1000" />
  </joint>
  <joint name="left_elbow_left_forearm_joint" type="revolute">
    <origin rpy="-3.141593 0.785398 -3.141593" xyz="0.01 0 0.0025" />
    <parent link="left_elbow" />
    <child link="left_forearm" />
    <axis xyz="0 -1 0" />
    <limit lower="0" upper="0" effort="1000" velocity="1000" />
  </joint>
  <joint name="left_forearm_left_wrist_roll_joint" type="revolute">
    <origin rpy="0 4.712734 0" xyz="0.0683 -0.0025 0" />
    <parent link="left_forearm" />
    <child link="left_wrist_roll" />
    <axis xyz="0 0 1" />
    <limit lower="-1.570796" upper="1.570796" effort="1000" velocity="1000" />
  </joint>
  <joint name="left_wrist_roll_left_wrist_tilt_joint" type="revolute">
    <origin rpy="0 1.570796 -4.712389" xyz="0 0 -0.00636" />
    <parent link="left_wrist_roll" />
    <child link="left_wrist_tilt" />
    <axis xyz="0 0 1" />
    <limit lower="-0.785398" upper="0.785398" effort="1000" velocity="1000" />
  </joint>
  <joint name="left_wrist_tilt_left_wrist_pan_joint" type="revolute">
    <origin rpy="-4.712389 0 0" xyz="0.002 0 0" />
    <parent link="left_wrist_tilt" />
    <child link="left_wrist_pan" />
    <axis xyz="0 0 1" />
    <limit lower="-0.785398" upper="0.785398" effort="1000" velocity="1000" />
  </joint>
  <joint name="left_wrist_pan_left_hand_joint" type="fixed">
    <origin xyz="0.012 0 0" />
    <parent link="left_wrist_pan" />
    <child link="left_hand" />
  </joint>

</robot>