<?xml version="1.0" encoding="utf-8"?>
<robot name="nefive">
  <material name="grey">
    <color rgba="0.5 0.5 0.5 1" />
  </material>
  <material name="black">
    <color rgba="0 0 0 1" />
  </material>
  <material name="Default-Material">
    <color rgba="1 1 1 1" />
  </material>
  <link name="base_link" />
  <link name="chassis">
    <inertial>
      <origin rpy="0 0 0" xyz="0 0 0" />
      <mass value="0.001" />
      <inertia ixx="0.000283500005025417" ixy="0" ixz="0" iyy="0.000283500005025417" iyz="0" izz="0.000323999993270263" />
    </inertial>
    <visual>
      <geometry>
        <box size="0.104 0.147 0.068" />
      </geometry>
      <material name="grey" />
    </visual>
    <collision>
      <geometry>
        <box size="0.104 0.147 0.068" />
      </geometry>
    </collision>
  </link>
  <link name="rear_right_wheel">
    <inertial>
      <origin rpy="0 0 0" xyz="0 0 0" />
      <mass value="0.001" />
      <inertia ixx="0.000283500005025417" ixy="0" ixz="0" iyy="0.000283500005025417" iyz="0" izz="0.000323999993270263" />
    </inertial>
    <visual>
      <origin rpy="-4.712389 0 0" xyz="0 -0.01 0" />
      <geometry>
        <cylinder length="0.02" radius="0.025" />
      </geometry>
      <material name="black" />
    </visual>
    <collision>
      <origin rpy="-4.712389 0 0" xyz="0 -0.01 0" />
      <geometry>
        <cylinder length="0.02" radius="0.025" />
      </geometry>
    </collision>
  </link>
  <link name="front_right_wheel">
    <inertial>
      <origin rpy="0 0 0" xyz="0 0 0" />
      <mass value="0.001" />
      <inertia ixx="0.000283500005025417" ixy="0" ixz="0" iyy="0.000283500005025417" iyz="0" izz="0.000323999993270263" />
    </inertial>
    <visual>
      <origin rpy="-1.570796 0 0" xyz="0 -0.01 0" />
      <geometry>
        <cylinder length="0.02" radius="0.025" />
      </geometry>
      <material name="black" />
    </visual>
    <collision>
      <origin rpy="-1.570796 0 0" xyz="0 -0.01 0" />
      <geometry>
        <cylinder length="0.02" radius="0.025" />
      </geometry>
    </collision>
  </link>
  <link name="rear_right_idler">
    <inertial>
      <origin rpy="0 0 0" xyz="0 0 0" />
      <mass value="0.001" />
      <inertia ixx="0.000283500005025417" ixy="0" ixz="0" iyy="0.000283500005025417" iyz="0" izz="0.000323999993270263" />
    </inertial>
    <visual>
      <origin rpy="-1.570796 0 0" xyz="0 -0.01 0" />
      <geometry>
        <cylinder length="0.02" radius="0.025" />
      </geometry>
      <material name="black" />
    </visual>
    <collision>
      <origin rpy="-1.570796 0 0" xyz="0 -0.01 0" />
      <geometry>
        <cylinder length="0.02" radius="0.025" />
      </geometry>
    </collision>
  </link>
  <link name="rear_left_idler">
    <inertial>
      <origin rpy="0 0 0" xyz="0 0 0" />
      <mass value="0.001" />
      <inertia ixx="0.000283500005025417" ixy="0" ixz="0" iyy="0.000283500005025417" iyz="0" izz="0.000323999993270263" />
    </inertial>
    <visual>
      <origin rpy="-1.570796 0 0" xyz="0 0.01 0" />
      <geometry>
        <cylinder length="0.02" radius="0.025" />
      </geometry>
      <material name="black" />
    </visual>
    <collision>
      <origin rpy="-1.570796 0 0" xyz="0 0.01 0" />
      <geometry>
        <cylinder length="0.02" radius="0.025" />
      </geometry>
    </collision>
  </link>
  <link name="front_left_wheel">
    <inertial>
      <origin rpy="0 0 0" xyz="0 0 0" />
      <mass value="0.001" />
      <inertia ixx="0.000283500005025417" ixy="0" ixz="0" iyy="0.000283500005025417" iyz="0" izz="0.000323999993270263" />
    </inertial>
    <visual>
      <origin rpy="-1.570796 0 0" xyz="0 0.01 0" />
      <geometry>
        <cylinder length="0.02" radius="0.025" />
      </geometry>
      <material name="black" />
    </visual>
    <collision>
      <origin rpy="-1.570796 0 0" xyz="0 0.01 0" />
      <geometry>
        <cylinder length="0.02" radius="0.025" />
      </geometry>
    </collision>
  </link>
  <link name="rear_left_wheel">
    <inertial>
      <origin rpy="0 0 0" xyz="0 0 0" />
      <mass value="0.001" />
      <inertia ixx="0.000283500005025417" ixy="0" ixz="0" iyy="0.000283500005025417" iyz="0" izz="0.000323999993270263" />
    </inertial>
    <visual>
      <origin rpy="-4.712389 0 0" xyz="0 0.01 0" />
      <geometry>
        <cylinder length="0.02" radius="0.025" />
      </geometry>
      <material name="black" />
    </visual>
    <collision>
      <origin rpy="-4.712389 0 0" xyz="0 0.01 0" />
      <geometry>
        <cylinder length="0.02" radius="0.025" />
      </geometry>
    </collision>
  </link>
  <link name="lower_torso">
    <inertial>
      <origin rpy="0 0 0" xyz="0 0 0" />
      <mass value="0.001" />
      <inertia ixx="0.000283500005025417" ixy="0" ixz="0" iyy="0.000283500005025417" iyz="0" izz="0.000323999993270263" />
    </inertial>
    <visual>
      <origin xyz="0 0 0.03" />
      <geometry>
        <box size="0.015 0.06 0.06" />
      </geometry>
      <material name="grey" />
    </visual>
    <collision>
      <origin xyz="0 0 0.03" />
      <geometry>
        <box size="0.015 0.06 0.06" />
      </geometry>
    </collision>
  </link>
  <link name="upper_torso">
    <inertial>
      <origin rpy="0 0 0" xyz="0 0 0" />
      <mass value="0.001" />
      <inertia ixx="0.000283500005025417" ixy="0" ixz="0" iyy="0.000283500005025417" iyz="0" izz="0.000323999993270263" />
    </inertial>
    <visual>
      <origin xyz="0 0 0.03" />
      <geometry>
        <box size="0.015 0.06 0.06" />
      </geometry>
      <material name="grey" />
    </visual>
    <collision>
      <origin xyz="0 0 0.03" />
      <geometry>
        <box size="0.015 0.06 0.06" />
      </geometry>
    </collision>
  </link>
  <link name="chest_box">
    <inertial>
      <origin rpy="0 0 0" xyz="0 0 0" />
      <mass value="0.001" />
      <inertia ixx="0.000283500005025417" ixy="0" ixz="0" iyy="0.000283500005025417" iyz="0" izz="0.000323999993270263" />
    </inertial>
    <visual>
      <origin xyz="0.0228 0 0.0564" />
      <geometry>
        <box size="0.05 0.07 0.05" />
      </geometry>
      <material name="grey" />
    </visual>
    <collision>
      <origin xyz="0.0228 0 0.0195" />
      <geometry>
        <box size="0.05 0.07 0.05" />
      </geometry>
    </collision>
  </link>
  <link name="head_pan">
    <inertial>
      <origin rpy="0 0 0" xyz="0 0 0" />
      <mass value="0.001" />
      <inertia ixx="0.000283500005025417" ixy="0" ixz="0" iyy="0.000283500005025417" iyz="0" izz="0.000323999993270263" />
    </inertial>
    <visual>
      <geometry>
        <cylinder length="0.002" radius="0.02" />
      </geometry>
      <material name="grey" />
    </visual>
    <collision>
      <geometry>
        <cylinder length="0.002" radius="0.02" />
      </geometry>
    </collision>
  </link>
  <link name="head_tilt">
    <inertial>
      <origin rpy="0 0 0" xyz="0 0 0" />
      <mass value="0.001" />
      <inertia ixx="0.000283500005025417" ixy="0" ixz="0" iyy="0.000283500005025417" iyz="0" izz="0.000323999993270263" />
    </inertial>
    <visual>
      <geometry>
        <box size="0.04 0.04 0.001" />
      </geometry>
      <material name="grey" />
    </visual>
    <collision>
      <geometry>
        <box size="0.04 0.04 0.001" />
      </geometry>
    </collision>
  </link>
  <link name="head">
    <inertial>
      <origin rpy="0 0 0" xyz="0 0 0" />
      <mass value="0.001" />
      <inertia ixx="0.000283500005025417" ixy="0" ixz="0" iyy="0.000283500005025417" iyz="0" izz="0.000323999993270263" />
    </inertial>
    <visual>
      <origin xyz="-0.0039 0 0.0283" />
      <geometry>
        <box size="0.107 0.11 0.054" />
      </geometry>
      <material name="grey" />
    </visual>
    <collision>
      <origin xyz="-0.0039 0 0.0283" />
      <geometry>
        <box size="0.107 0.11 0.054" />
      </geometry>
    </collision>
  </link>
  <link name="eyes">
    <inertial>
      <origin rpy="0 0 0" xyz="0 0 0" />
      <mass value="0.001" />
      <inertia ixx="0.000283500005025417" ixy="0" ixz="0" iyy="0.000283500005025417" iyz="0" izz="0.000323999993270263" />
    </inertial>
    <visual>
      <geometry>
        <cylinder length="0" radius="0" />
      </geometry>
      <material name="Default-Material" />
    </visual>
    <collision>
      <geometry>
        <cylinder length="0" radius="0" />
      </geometry>
    </collision>
  </link>
  <link name="left_eye_ring">
    <inertial>
      <origin rpy="0 0 0" xyz="0 0 0" />
      <mass value="0.001" />
      <inertia ixx="0.000283500005025417" ixy="0" ixz="0" iyy="0.000283500005025417" iyz="0" izz="0.000323999993270263" />
    </inertial>
    <visual>
      <origin rpy="0 1.570451 0" />
      <geometry>
        <cylinder length="0.002" radius="0.02" />
      </geometry>
      <material name="Default-Material" />
    </visual>
    <collision>
      <origin rpy="0 1.570451 0" />
      <geometry>
        <cylinder length="0.002" radius="0.02" />
      </geometry>
    </collision>
  </link>
  <link name="left_eye_inner">
    <inertial>
      <origin rpy="0 0 0" xyz="0 0 0" />
      <mass value="0.001" />
      <inertia ixx="0.000283500005025417" ixy="0" ixz="0" iyy="0.000283500005025417" iyz="0" izz="0.000323999993270263" />
    </inertial>
    <visual>
      <origin rpy="0 1.570451 0" xyz="0.0006 0 0" />
      <geometry>
        <cylinder length="0.002" radius="0.01" />
      </geometry>
      <material name="black" />
    </visual>
    <collision>
      <origin rpy="0 1.570451 0" xyz="0.0006 0 0" />
      <geometry>
        <cylinder length="0.002" radius="0.01" />
      </geometry>
    </collision>
  </link>
  <link name="left_camera">
    <inertial>
      <origin rpy="0 0 0" xyz="0 0 0" />
      <mass value="0.001" />
      <inertia ixx="0.000283500005025417" ixy="0" ixz="0" iyy="0.000283500005025417" iyz="0" izz="0.000323999993270263" />
    </inertial>
  </link>
  <link name="right_eye_ring">
    <inertial>
      <origin rpy="0 0 0" xyz="0 0 0" />
      <mass value="0.001" />
      <inertia ixx="0.000283500005025417" ixy="0" ixz="0" iyy="0.000283500005025417" iyz="0" izz="0.000323999993270263" />
    </inertial>
    <visual>
      <origin rpy="0 1.570451 0" />
      <geometry>
        <cylinder length="0.002" radius="0.02" />
      </geometry>
      <material name="Default-Material" />
    </visual>
    <collision>
      <origin rpy="0 1.570451 0" />
      <geometry>
        <cylinder length="0.002" radius="0.02" />
      </geometry>
    </collision>
  </link>
  <link name="right_eye_inner">
    <inertial>
      <origin rpy="0 0 0" xyz="0 0 0" />
      <mass value="0.001" />
      <inertia ixx="0.000283500005025417" ixy="0" ixz="0" iyy="0.000283500005025417" iyz="0" izz="0.000323999993270263" />
    </inertial>
    <visual>
      <origin rpy="0 1.570451 0" xyz="0.0006 0 0" />
      <geometry>
        <cylinder length="0.002" radius="0.01" />
      </geometry>
      <material name="black" />
    </visual>
    <collision>
      <origin rpy="0 1.570451 0" xyz="0.0006 0 0" />
      <geometry>
        <cylinder length="0.002" radius="0.01" />
      </geometry>
    </collision>
  </link>
  <link name="right_camera">
    <inertial>
      <origin rpy="0 0 0" xyz="0 0 0" />
      <mass value="0.001" />
      <inertia ixx="0.000283500005025417" ixy="0" ixz="0" iyy="0.000283500005025417" iyz="0" izz="0.000323999993270263" />
    </inertial>
  </link>
  <link name="arms">
    <inertial>
      <origin rpy="0 0 0" xyz="0 0 0" />
      <mass value="0.001" />
      <inertia ixx="0.000283500005025417" ixy="0" ixz="0" iyy="0.000283500005025417" iyz="0" izz="0.000323999993270263" />
    </inertial>
  </link>
  <link name="right_arm">
    <inertial>
      <origin rpy="0 0 0" xyz="0 0 0" />
      <mass value="0.001" />
      <inertia ixx="0.000283500005025417" ixy="0" ixz="0" iyy="0.000283500005025417" iyz="0" izz="0.000323999993270263" />
    </inertial>
  </link>
  <link name="right_shoulder_tilt">
    <inertial>
      <origin rpy="0 0 0" xyz="0 0 0" />
      <mass value="0.001" />
      <inertia ixx="0.000283500005025417" ixy="0" ixz="0" iyy="0.000283500005025417" iyz="0" izz="0.000323999993270263" />
    </inertial>
    <visual>
      <origin rpy="0 1.570451 0" />
      <geometry>
        <cylinder length="0.02" radius="0.0005" />
      </geometry>
      <material name="grey" />
    </visual>
    <collision>
      <origin rpy="0 1.570451 0" />
      <geometry>
        <cylinder length="0.02" radius="0.0005" />
      </geometry>
    </collision>
  </link>
  <link name="right_shoulder_pan">
    <inertial>
      <origin rpy="0 0 0" xyz="0 0 0" />
      <mass value="0.001" />
      <inertia ixx="0.000283500005025417" ixy="0" ixz="0" iyy="0.000283500005025417" iyz="0" izz="0.000323999993270263" />
    </inertial>
    <visual>
      <origin rpy="-4.712389 0 0" xyz="0 -0.002 0" />
      <geometry>
        <cylinder length="0.004" radius="0.0005" />
      </geometry>
      <material name="grey" />
    </visual>
    <collision>
      <origin rpy="-4.712389 0 0" xyz="0 -0.002 0" />
      <geometry>
        <cylinder length="0.004" radius="0.0005" />
      </geometry>
    </collision>
  </link>
  <link name="right_shoulder_rotate">
    <inertial>
      <origin rpy="0 0 0" xyz="0 0 0" />
      <mass value="0.001" />
      <inertia ixx="0.000283500005025417" ixy="0" ixz="0" iyy="0.000283500005025417" iyz="0" izz="0.000323999993270263" />
    </inertial>
    <visual>
      <origin rpy="-4.712389 0 -4.712389" xyz="0.0001 -0.002 0" />
      <geometry>
        <cylinder length="0.004" radius="0.0005" />
      </geometry>
      <material name="grey" />
    </visual>
    <visual>
      <origin rpy="0 1.570451 0" xyz="0.031 -0.002 0" />
      <geometry>
        <cylinder length="-0.06" radius="0.005" />
      </geometry>
      <material name="grey" />
    </visual>
    <collision>
      <origin rpy="-4.712389 0 -4.712389" xyz="0.00217 -0.002 0" />
      <geometry>
        <cylinder length="0.004" radius="0.0005" />
      </geometry>
    </collision>
    <collision>
      <origin rpy="0 1.570451 0" xyz="0.031 -0.002 0" />
      <geometry>
        <cylinder length="-0.06" radius="0.005" />
      </geometry>
    </collision>
  </link>
  <link name="right_elbow">
    <inertial>
      <origin rpy="0 0 0" xyz="0 0 0" />
      <mass value="0.001" />
      <inertia ixx="0.000283500005025417" ixy="0" ixz="0" iyy="0.000283500005025417" iyz="0" izz="0.000323999993270263" />
    </inertial>
    <visual>
      <origin rpy="0 1.570451 0" />
      <geometry>
        <cylinder length="0.02" radius="0.0005" />
      </geometry>
      <material name="grey" />
    </visual>
    <collision>
      <origin rpy="0 1.570451 0" />
      <geometry>
        <cylinder length="0.02" radius="0.0005" />
      </geometry>
    </collision>
  </link>
  <link name="right_forearm">
    <inertial>
      <origin rpy="0 0 0" xyz="0 0 0" />
      <mass value="0.001" />
      <inertia ixx="0.000283500005025417" ixy="0" ixz="0" iyy="0.000283500005025417" iyz="0" izz="0.000323999993270263" />
    </inertial>
    <visual>
      <origin rpy="0 1.570451 0" xyz="0.035 -0.0025 0" />
      <geometry>
        <cylinder length="0.07" radius="0.005" />
      </geometry>
      <material name="grey" />
    </visual>
    <collision>
      <origin rpy="0 1.570451 0" xyz="0.035 -0.0025 0" />
      <geometry>
        <cylinder length="0.07" radius="0.005" />
      </geometry>
    </collision>
  </link>
  <link name="right_wrist_roll">
    <inertial>
      <origin rpy="0 0 0" xyz="0 0 0" />
      <mass value="0.001" />
      <inertia ixx="0.000283500005025417" ixy="0" ixz="0" iyy="0.000283500005025417" iyz="0" izz="0.000323999993270263" />
    </inertial>
    <visual>
      <geometry>
        <cylinder length="0.01" radius="0.0005" />
      </geometry>
      <material name="grey" />
    </visual>
    <collision>
      <geometry>
        <cylinder length="0.01" radius="0.0005" />
      </geometry>
    </collision>
  </link>
  <link name="right_wrist_tilt">
    <inertial>
      <origin rpy="0 0 0" xyz="0 0 0" />
      <mass value="0.001" />
      <inertia ixx="0.000283500005025417" ixy="0" ixz="0" iyy="0.000283500005025417" iyz="0" izz="0.000323999993270263" />
    </inertial>
    <visual>
      <geometry>
        <cylinder length="0.01" radius="0.0005" />
      </geometry>
      <material name="grey" />
    </visual>
    <collision>
      <geometry>
        <cylinder length="0.01" radius="0.0005" />
      </geometry>
    </collision>
  </link>
  <link name="right_wrist_pan">
    <inertial>
      <origin rpy="0 0 0" xyz="0 0 0" />
      <mass value="0.001" />
      <inertia ixx="0.000283500005025417" ixy="0" ixz="0" iyy="0.000283500005025417" iyz="0" izz="0.000323999993270263" />
    </inertial>
    <visual>
      <geometry>
        <cylinder length="0.01" radius="0.0005" />
      </geometry>
      <material name="grey" />
    </visual>
    <collision>
      <geometry>
        <cylinder length="0.01" radius="0.0005" />
      </geometry>
    </collision>
  </link>
  <link name="right_hand">
    <inertial>
      <origin rpy="0 0 0" xyz="0 0 0" />
      <mass value="0.001" />
      <inertia ixx="2.93333323497791E-06" ixy="0" ixz="0" iyy="2.93333323497791E-06" iyz="0" izz="2.93333323497791E-06" />
    </inertial>
    <visual>
      <geometry>
        <box size="0.02 0.02 0.02" />
      </geometry>
      <material name="grey" />
    </visual>
  </link>
  <link name="left_arm">
    <inertial>
      <origin rpy="0 0 0" xyz="0 0 0" />
      <mass value="0.001" />
      <inertia ixx="0.000283500005025417" ixy="0" ixz="0" iyy="0.000283500005025417" iyz="0" izz="0.000323999993270263" />
    </inertial>
  </link>
  <link name="left_shoulder_tilt">
    <inertial>
      <origin rpy="0 0 0" xyz="0 0 0" />
      <mass value="0.001" />
      <inertia ixx="0.000283500005025417" ixy="0" ixz="0" iyy="0.000283500005025417" iyz="0" izz="0.000323999993270263" />
    </inertial>
    <visual>
      <origin rpy="0 1.570451 0" />
      <geometry>
        <cylinder length="0.02" radius="0.0005" />
      </geometry>
      <material name="grey" />
    </visual>
    <collision>
      <origin rpy="0 1.570451 0" />
      <geometry>
        <cylinder length="0.02" radius="0.0005" />
      </geometry>
    </collision>
  </link>
  <link name="left_shoulder_pan">
    <inertial>
      <origin rpy="0 0 0" xyz="0 0 0" />
      <mass value="0.001" />
      <inertia ixx="0.000283500005025417" ixy="0" ixz="0" iyy="0.000283500005025417" iyz="0" izz="0.000323999993270263" />
    </inertial>
    <visual>
      <origin rpy="-4.712389 0 0" xyz="0 -0.002 0" />
      <geometry>
        <cylinder length="0.004" radius="0.0005" />
      </geometry>
      <material name="grey" />
    </visual>
    <collision>
      <origin rpy="-4.712389 0 0" xyz="0 -0.002 0" />
      <geometry>
        <cylinder length="0.004" radius="0.0005" />
      </geometry>
    </collision>
  </link>
  <link name="left_shoulder_rotate">
    <inertial>
      <origin rpy="0 0 0" xyz="0 0 0" />
      <mass value="0.001" />
      <inertia ixx="0.000283500005025417" ixy="0" ixz="0" iyy="0.000283500005025417" iyz="0" izz="0.000323999993270263" />
    </inertial>
    <visual>
      <origin rpy="-4.712389 0 -4.712389" xyz="0.0001 -0.002 0" />
      <geometry>
        <cylinder length="0.004" radius="0.0005" />
      </geometry>
      <material name="grey" />
    </visual>
    <visual>
      <origin rpy="0 1.570451 0" xyz="0.031 -0.002 0" />
      <geometry>
        <cylinder length="-0.06" radius="0.005" />
      </geometry>
      <material name="grey" />
    </visual>
    <collision>
      <origin rpy="-4.712389 0 -4.712389" xyz="0.00217 -0.002 0" />
      <geometry>
        <cylinder length="0.004" radius="0.0005" />
      </geometry>
    </collision>
    <collision>
      <origin rpy="0 1.570451 0" xyz="0.031 -0.002 0" />
      <geometry>
        <cylinder length="-0.06" radius="0.005" />
      </geometry>
    </collision>
  </link>
  <link name="left_elbow">
    <inertial>
      <origin rpy="0 0 0" xyz="0 0 0" />
      <mass value="0.001" />
      <inertia ixx="0.000283500005025417" ixy="0" ixz="0" iyy="0.000283500005025417" iyz="0" izz="0.000323999993270263" />
    </inertial>
    <visual>
      <origin rpy="0 1.570451 0" />
      <geometry>
        <cylinder length="0.02" radius="0.0005" />
      </geometry>
      <material name="grey" />
    </visual>
    <collision>
      <origin rpy="0 1.570451 0" />
      <geometry>
        <cylinder length="0.02" radius="0.0005" />
      </geometry>
    </collision>
  </link>
  <link name="left_forearm">
    <inertial>
      <origin rpy="0 0 0" xyz="0 0 0" />
      <mass value="0.001" />
      <inertia ixx="0.000283500005025417" ixy="0" ixz="0" iyy="0.000283500005025417" iyz="0" izz="0.000323999993270263" />
    </inertial>
    <visual>
      <origin rpy="0 1.570451 0" xyz="0.035 -0.0025 0" />
      <geometry>
        <cylinder length="0.07" radius="0.005" />
      </geometry>
      <material name="grey" />
    </visual>
    <collision>
      <origin rpy="0 1.570451 0" xyz="0.035 -0.0025 0" />
      <geometry>
        <cylinder length="0.07" radius="0.005" />
      </geometry>
    </collision>
  </link>
  <link name="left_wrist_roll">
    <inertial>
      <origin rpy="0 0 0" xyz="0 0 0" />
      <mass value="0.001" />
      <inertia ixx="0.000283500005025417" ixy="0" ixz="0" iyy="0.000283500005025417" iyz="0" izz="0.000323999993270263" />
    </inertial>
    <visual>
      <geometry>
        <cylinder length="0.01" radius="0.0005" />
      </geometry>
      <material name="grey" />
    </visual>
    <collision>
      <geometry>
        <cylinder length="0.01" radius="0.0005" />
      </geometry>
    </collision>
  </link>
  <link name="left_wrist_tilt">
    <inertial>
      <origin rpy="0 0 0" xyz="0 0 0" />
      <mass value="0.001" />
      <inertia ixx="0.000283500005025417" ixy="0" ixz="0" iyy="0.000283500005025417" iyz="0" izz="0.000323999993270263" />
    </inertial>
    <visual>
      <geometry>
        <cylinder length="0.01" radius="0.0005" />
      </geometry>
      <material name="grey" />
    </visual>
    <collision>
      <geometry>
        <cylinder length="0.01" radius="0.0005" />
      </geometry>
    </collision>
  </link>
  <link name="left_wrist_pan">
    <inertial>
      <origin rpy="0 0 0" xyz="0 0 0" />
      <mass value="0.001" />
      <inertia ixx="0.000283500005025417" ixy="0" ixz="0" iyy="0.000283500005025417" iyz="0" izz="0.000323999993270263" />
    </inertial>
    <visual>
      <geometry>
        <cylinder length="0.01" radius="0.0005" />
      </geometry>
      <material name="grey" />
    </visual>
    <collision>
      <geometry>
        <cylinder length="0.01" radius="0.0005" />
      </geometry>
    </collision>
  </link>
  <link name="left_hand">
    <inertial>
      <origin rpy="0 0 0" xyz="0 0 0" />
      <mass value="0.001" />
      <inertia ixx="2.93333323497791E-06" ixy="0" ixz="0" iyy="2.93333323497791E-06" iyz="0" izz="2.93333323497791E-06" />
    </inertial>
    <visual>
      <geometry>
        <box size="0.02 0.02 0.02" />
      </geometry>
      <material name="grey" />
    </visual>
  </link>
  <link name="upper_tracks">
    <inertial>
      <origin rpy="0 0 0" xyz="0 0 0" />
      <mass value="1" />
      <inertia ixx="1" ixy="0" ixz="0" iyy="1" iyz="0" izz="1" />
    </inertial>
    <visual>
      <origin rpy="0 0.418879 0" xyz="0.0209 -0.088 0.021" />
      <geometry>
        <box size="0.07 0.02 0.01" />
      </geometry>
      <material name="black" />
    </visual>
    <visual>
      <origin rpy="0 0.418879 0" xyz="0.0209 0.088 0.021" />
      <geometry>
        <box size="0.07 0.02 0.01" />
      </geometry>      
      <material name="black" />
    </visual>
    <collision>
      <origin rpy="0 0.418879 0" xyz="0.0209 -0.088 0.021" />
      <geometry>
        <box size="0.07 0.02 0.01" />
      </geometry>
    </collision>
    <collision>
      <origin rpy="0 0.418879 0" xyz="0.0209 0.088 0.021" />
      <geometry>
        <box size="0.07 0.02 0.01" />
      </geometry>
    </collision>
  </link>
  <joint name="base_link_chassis_joint" type="fixed">
    <parent link="base_link" />
    <child link="chassis" />
  </joint>
  <joint name="base_link_rear_right_wheel_joint" type="continuous">
    <origin xyz="-0.07 -0.078 -0.022" />
    <parent link="chassis" />
    <child link="rear_right_wheel" />
    <axis xyz="0 1 0" />
  </joint>
  <joint name="base_link_front_right_wheel_joint" type="continuous">
    <origin xyz="0.07 -0.078 -0.022" />
    <parent link="chassis" />
    <child link="front_right_wheel" />
    <axis xyz="0 1 0" />
  </joint>
  <joint name="base_link_rear_right_idler_joint" type="fixed">
    <origin xyz="-0.0402 -0.078 0.0271" />
    <parent link="chassis" />
    <child link="rear_right_idler" />
  </joint>
  <joint name="base_link_rear_left_idler_joint" type="fixed">
    <origin xyz="-0.0402 0.078 0.0271" />
    <parent link="chassis" />
    <child link="rear_left_idler" />
  </joint>
  <joint name="base_link_front_left_wheel_joint" type="continuous">
    <origin xyz="0.07 0.078 -0.022" />
    <parent link="chassis" />
    <child link="front_left_wheel" />
    <axis xyz="0 1 0" />
  </joint>
  <joint name="base_link_rear_left_wheel_joint" type="continuous">
    <origin xyz="-0.07 0.078 -0.022" />
    <parent link="chassis" />
    <child link="rear_left_wheel" />
    <axis xyz="0 1 0" />
  </joint>
  <joint name="base_link_lower_torso_joint" type="fixed">
    <origin rpy="0 5.497787 0" xyz="-0.0241 0 0.0285" />
    <parent link="chassis" />
    <child link="lower_torso" />
  </joint>
  <joint name="lower_torso_upper_torso_joint" type="fixed">
    <origin rpy="0 1.570451 0" xyz="0 0 0.06" />
    <parent link="lower_torso" />
    <child link="upper_torso" />
  </joint>
  <joint name="upper_torso_chest_box_joint" type="fixed">
    <origin rpy="0 5.497787 0" xyz="0.0305 0 0.0269" />
    <parent link="upper_torso" />
    <child link="chest_box" />
  </joint>
  <joint name="chest_box_head_pan_joint" type="revolute">
    <origin xyz="0.025 0 0.0819" />
    <parent link="chest_box" />
    <child link="head_pan" />
    <axis xyz="0 0 1" />
    <limit lower="-0.785398" upper="0.785398" effort="1000" velocity="1000" />
  </joint>
  <joint name="head_pan_head_tilt_joint" type="revolute">
    <origin xyz="0 0 0.035" />
    <parent link="head_pan" />
    <child link="head_tilt" />
    <axis xyz="0 -1 0" />
    <limit lower="-0.785398" upper="0.785398" effort="1000" velocity="1000" />
  </joint>
  <joint name="head_tilt_head_joint" type="fixed">
    <parent link="head_tilt" />
    <child link="head" />
  </joint>
  <joint name="head_eyes_joint" type="fixed">
    <origin xyz="0.05 0 0.03" />
    <parent link="head" />
    <child link="eyes" />
  </joint>
  <joint name="eyes_left_eye_ring_joint" type="fixed">
    <origin xyz="0 0.03 0" />
    <parent link="eyes" />
    <child link="left_eye_ring" />
  </joint>
  <joint name="left_eye_ring_left_eye_inner_joint" type="fixed">
    <parent link="left_eye_ring" />
    <child link="left_eye_inner" />
  </joint>
  <joint name="left_eye_inner_left_camera_joint" type="fixed">
    <parent link="left_eye_inner" />
    <child link="left_camera" />
  </joint>
  <joint name="eyes_right_eye_ring_joint" type="fixed">
    <origin xyz="0 -0.03 0" />
    <parent link="eyes" />
    <child link="right_eye_ring" />
  </joint>
  <joint name="right_eye_ring_right_eye_inner_joint" type="fixed">
    <parent link="right_eye_ring" />
    <child link="right_eye_inner" />
  </joint>
  <joint name="right_eye_inner_right_camera_joint" type="fixed">
    <parent link="right_eye_inner" />
    <child link="right_camera" />
  </joint>
  <joint name="chest_box_arms_joint" type="fixed">
    <origin xyz="0.025 0 0.075" />
    <parent link="chest_box" />
    <child link="arms" />
  </joint>
  <joint name="arms_right_arm_joint" type="fixed">
    <origin xyz="0 -0.06 0" />
    <parent link="arms" />
    <child link="right_arm" />
  </joint>
  <joint name="right_arm_right_shoulder_tilt_joint" type="revolute">
    <origin rpy="0 0.785398 0" />
    <parent link="right_arm" />
    <child link="right_shoulder_tilt" />
    <axis xyz="1 0 0" />
    <limit lower="-0.610865" upper="0.436332" effort="1000" velocity="1000" />
  </joint>
  <joint name="right_shoulder_tilt_right_shoulder_pan_joint" type="revolute">
    <origin rpy="0 0.785398 0" xyz="0 -0.001 0" />
    <parent link="right_shoulder_tilt" />
    <child link="right_shoulder_pan" />
    <axis xyz="0 -1 0" />
    <limit lower="-1.570796" upper="1.570796" effort="1000" velocity="1000" />
  </joint>
  <joint name="right_shoulder_pan_right_shoulder_rotate_joint" type="revolute">
    <origin rpy="0 0.785398 0" xyz="0 -0.0048 0" />
    <parent link="right_shoulder_pan" />
    <child link="right_shoulder_rotate" />
    <axis xyz="1 0 0" />
    <limit lower="-1.570796" upper="1.570796" effort="1000" velocity="1000" />
  </joint>
  <joint name="right_shoulder_rotate_right_elbow_joint" type="revolute">
    <origin xyz="0.075 0 0" />
    <parent link="right_shoulder_rotate" />
    <child link="right_elbow" />
    <axis xyz="0 -1 0" />
    <limit lower="0" upper="0" effort="1000" velocity="1000" />
  </joint>
  <joint name="right_elbow_right_forearm_joint" type="revolute">
    <origin rpy="-3.141593 5.497787 -3.141593" xyz="0.01 0 0.0025" />
    <parent link="right_elbow" />
    <child link="right_forearm" />
    <axis xyz="0 -1 0" />
    <limit lower="0" upper="0" effort="1000" velocity="1000" />
  </joint>
  <joint name="right_forearm_right_wrist_roll_joint" type="revolute">
    <origin rpy="0 4.712389 0" xyz="0.0683 -0.0025 0" />
    <parent link="right_forearm" />
    <child link="right_wrist_roll" />
    <axis xyz="0 0 1" />
    <limit lower="-1.570796" upper="1.570796" effort="1000" velocity="1000" />
  </joint>
  <joint name="right_wrist_roll_right_wrist_tilt_joint" type="revolute">
    <origin rpy="0 1.570796 -4.712389" xyz="0 0 -0.00636" />
    <parent link="right_wrist_roll" />
    <child link="right_wrist_tilt" />
    <axis xyz="0 0 1" />
    <limit lower="-0.785398" upper="0.785398" effort="1000" velocity="1000" />
  </joint>
  <joint name="right_wrist_tilt_right_wrist_pan_joint" type="revolute">
    <origin rpy="-4.712389 0 0" xyz="0.002 0 0" />
    <parent link="right_wrist_tilt" />
    <child link="right_wrist_pan" />
    <axis xyz="0 0 1" />
    <limit lower="-0.785398" upper="0.785398" effort="1000" velocity="1000" />
  </joint>
  <joint name="right_wrist_pan_right_hand_joint" type="fixed">
    <origin xyz="0.012 0 0" />
    <parent link="right_wrist_pan" />
    <child link="right_hand" />
  </joint>
  <joint name="arms_left_arm_joint" type="fixed">
    <origin rpy="0 0 -3.141593" xyz="0 0.06 0" />
    <parent link="arms" />
    <child link="left_arm" />
  </joint>
  <joint name="left_arm_left_shoulder_tilt_joint" type="revolute">
    <origin rpy="0 5.497787 0" />
    <parent link="left_arm" />
    <child link="left_shoulder_tilt" />
    <axis xyz="1 0 0" />
    <limit lower="-0.610865" upper="0.436332" effort="1000" velocity="1000" />
  </joint>
  <joint name="left_shoulder_tilt_left_shoulder_pan_joint" type="revolute">
    <origin rpy="-3.141593 0.785398 -3.141593" xyz="0 -0.001 0" />
    <parent link="left_shoulder_tilt" />
    <child link="left_shoulder_pan" />
    <axis xyz="0 -1 0" />
    <limit lower="-1.570796" upper="1.570796" effort="1000" velocity="1000" />
  </joint>
  <joint name="left_shoulder_pan_left_shoulder_rotate_joint" type="revolute">
    <origin rpy="0 5.497787 0" xyz="0 -0.0048 0" />
    <parent link="left_shoulder_pan" />
    <child link="left_shoulder_rotate" />
    <axis xyz="1 0 0" />
    <limit lower="-1.570796" upper="1.570796" effort="1000" velocity="1000" />
  </joint>
  <joint name="left_shoulder_rotate_left_elbow_joint" type="revolute">
    <origin xyz="0.075 0 0" />
    <parent link="left_shoulder_rotate" />
    <child link="left_elbow" />
    <axis xyz="0 -1 0" />
    <limit lower="0" upper="0" effort="1000" velocity="1000" />
  </joint>
  <joint name="left_elbow_left_forearm_joint" type="revolute">
    <origin rpy="-3.141593 0.785398 -3.141593" xyz="0.01 0 0.0025" />
    <parent link="left_elbow" />
    <child link="left_forearm" />
    <axis xyz="0 -1 0" />
    <limit lower="0" upper="0" effort="1000" velocity="1000" />
  </joint>
  <joint name="left_forearm_left_wrist_roll_joint" type="revolute">
    <origin rpy="0 4.712734 0" xyz="0.0683 -0.0025 0" />
    <parent link="left_forearm" />
    <child link="left_wrist_roll" />
    <axis xyz="0 0 1" />
    <limit lower="-1.570796" upper="1.570796" effort="1000" velocity="1000" />
  </joint>
  <joint name="left_wrist_roll_left_wrist_tilt_joint" type="revolute">
    <origin rpy="0 1.570796 -4.712389" xyz="0 0 -0.00636" />
    <parent link="left_wrist_roll" />
    <child link="left_wrist_tilt" />
    <axis xyz="0 0 1" />
    <limit lower="-0.785398" upper="0.785398" effort="1000" velocity="1000" />
  </joint>
  <joint name="left_wrist_tilt_left_wrist_pan_joint" type="revolute">
    <origin rpy="-4.712389 0 0" xyz="0.002 0 0" />
    <parent link="left_wrist_tilt" />
    <child link="left_wrist_pan" />
    <axis xyz="0 0 1" />
    <limit lower="-0.785398" upper="0.785398" effort="1000" velocity="1000" />
  </joint>
  <joint name="left_wrist_pan_left_hand_joint" type="fixed">
    <origin xyz="0.012 0 0" />
    <parent link="left_wrist_pan" />
    <child link="left_hand" />
  </joint>
  <joint name="" type="fixed">
    <parent link="chassis" />
    <child link="upper_tracks" />
  </joint>
  <gazebo>
  <plugin name="gazebo_ros_control" filename="libgazebo_ros_control.so">
    <robotNamespace>/nefive</robotNamespace>
  </plugin>
  <plugin name="differential_drive_controller" filename="libgazebo_ros_diff_drive.so">
    <legacyMode>false</legacyMode>
    <alwaysOn>true</alwaysOn>
    <publishWheelTF>true</publishWheelTF>
    <publishTf>1</publishTf>
    <publishWheelJointState>true</publishWheelJointState>
    <updateRate>100.0</updateRate>
    <leftJoint>base_link_rear_left_wheel_joint</leftJoint>
    <rightJoint>base_link_rear_right_wheel_joint</rightJoint>
    <wheelSeparation>1.0</wheelSeparation>
    <wheelDiameter>0.58</wheelDiameter>
    <wheelAcceleration>1.0</wheelAcceleration>
    <torque>20</torque>
    <commandTopic>/nefive/cmd_vel</commandTopic>
    <odometryTopic>odom</odometryTopic>
    <odometryFrame>odom</odometryFrame>
    <robotBaseFrame>base_link</robotBaseFrame>
  </plugin>
  <plugin name="gazebo_ros_imu_controller_base" filename="libgazebo_ros_imu.so">
    <!-- <robotNamespace></robotNamespace> -->
    <topicName>base/imu/data</topicName>
    <serviceName>base/imu/service</serviceName>
    <bodyName>base_link</bodyName>
    <gaussianNoise>0</gaussianNoise>
    <rpyOffsets>0 0 0</rpyOffsets>
    <updateRate>30.0</updateRate>
    <alwaysOn>true</alwaysOn>
    <gaussianNoise>0</gaussianNoise>
  </plugin>
  <plugin name="gazebo_ros_imu_controller_head" filename="libgazebo_ros_imu.so">
    <!-- <robotNamespace></robotNamespace> -->
    <topicName>head/imu/data</topicName>
    <serviceName>head/imu/service</serviceName>
    <bodyName>head</bodyName>
    <gaussianNoise>0</gaussianNoise>
    <rpyOffsets>0 0 0</rpyOffsets>
    <updateRate>30.0</updateRate>
    <alwaysOn>true</alwaysOn>
    <gaussianNoise>0</gaussianNoise>
  </plugin>
</gazebo>
<gazebo reference="base_link">
  <kp>100000.0</kp>
  <kd>100000.0</kd>
  <mu1>10.0</mu1>
  <mu2>10.0</mu2>
  <material>Gazebo/Grey</material>
</gazebo>
<gazebo reference="chassis">
  <material>Gazebo/Grey</material>
</gazebo>
<gazebo reference="upper_tracks">
  <material>Gazebo/Black</material>
</gazebo>
<gazebo reference="rear_right_wheel">
  <material>Gazebo/Black</material>
</gazebo>
<gazebo reference="front_right_wheel">
  <material>Gazebo/Black</material>
</gazebo>
<gazebo reference="rear_right_idler">
  <material>Gazebo/Black</material>
</gazebo>
<gazebo reference="rear_left_idler">
  <material>Gazebo/Black</material>
</gazebo>
<gazebo reference="front_left_wheel">
  <material>Gazebo/Black</material>
</gazebo>
<gazebo reference="rear_left_wheel">
  <material>Gazebo/Black</material>
</gazebo>
<gazebo reference="lower_torso">
  <material>Gazebo/Grey</material>
</gazebo>
<gazebo reference="upper_torso">
  <material>Gazebo/Grey</material>
</gazebo>
<gazebo reference="chest_box">
  <material>Gazebo/Grey</material>
</gazebo>
<gazebo reference="head_pan">
  <material>Gazebo/Grey</material>
</gazebo>
<gazebo reference="head_tilt">
  <material>Gazebo/Grey</material>
</gazebo>
<gazebo reference="head">
  <material>Gazebo/Grey</material>
</gazebo>
<gazebo reference="left_eye_ring">
  <material>Gazebo/White</material>
</gazebo>
<gazebo reference="left_eye_inner">
  <material>Gazebo/Black</material>
</gazebo>
<gazebo reference="right_eye_ring">
  <material>Gazebo/White</material>
</gazebo>
<gazebo reference="right_eye_inner">
  <material>Gazebo/Black</material>
</gazebo>
<gazebo reference="right_arm">
  <material>Gazebo/Grey</material>
</gazebo>
<gazebo reference="right_shoulder_tilt">
  <material>Gazebo/Grey</material>
</gazebo>
<gazebo reference="right_shoulder_pan">
  <material>Gazebo/Grey</material>
</gazebo>
<gazebo reference="right_shoulder_rotate">
  <material>Gazebo/Grey</material>
</gazebo>
<gazebo reference="right_elbow">
  <material>Gazebo/Grey</material>
</gazebo>
<gazebo reference="right_forearm">
  <material>Gazebo/Grey</material>
</gazebo>
<gazebo reference="right_wrist_roll">
  <material>Gazebo/Grey</material>
</gazebo>
<gazebo reference="right_wrist_tilt">
  <material>Gazebo/Grey</material>
</gazebo>
<gazebo reference="right_wrist_pan">
  <material>Gazebo/Grey</material>
</gazebo>
<gazebo reference="right_hand">
  <material>Gazebo/Grey</material>
</gazebo>
<gazebo reference="left_arm">
  <material>Gazebo/Grey</material>
</gazebo>
<gazebo reference="left_shoulder_tilt">
  <material>Gazebo/Grey</material>
</gazebo>
<gazebo reference="left_shoulder_pan">
  <material>Gazebo/Grey</material>
</gazebo>
<gazebo reference="left_shoulder_rotate">
  <material>Gazebo/Grey</material>
</gazebo>
<gazebo reference="left_elbow">
  <material>Gazebo/Grey</material>
</gazebo>
<gazebo reference="left_forearm">
  <material>Gazebo/Grey</material>
</gazebo>
<gazebo reference="left_wrist_roll">
  <material>Gazebo/Grey</material>
</gazebo>
<gazebo reference="left_wrist_tilt">
  <material>Gazebo/Grey</material>
</gazebo>
<gazebo reference="left_wrist_pan">
  <material>Gazebo/Grey</material>
</gazebo>
<gazebo reference="left_hand">
  <material>Gazebo/Grey</material>
</gazebo>
<gazebo reference="base_link_fixed_joint_lump__left_track_upper_visual_2">
  <material>Gazebo/Black</material>
</gazebo>
<transmission name="rear_left_wheel_transmission">
  <type>transmission_interface/SimpleTransmission</type>
  <joint name="base_link_rear_left_wheel_joint">
    <hardwareInterface>hardware_interface/VelocityJointInterface</hardwareInterface>
  </joint>
  <actuator name="rear_left_wheel_actuator">
    <mechanicalReduction>7</mechanicalReduction>
    <hardwareInterface>VelocityJointInterface</hardwareInterface>
  </actuator>
</transmission>
<transmission name="rear_right_wheel_transmission">
  <type>transmission_interface/SimpleTransmission</type>
  <joint name="base_link_rear_right_wheel_joint">
    <hardwareInterface>hardware_interface/VelocityJointInterface</hardwareInterface>
  </joint>
  <actuator name="right_wheel_actuator">
    <mechanicalReduction>7</mechanicalReduction>
    <hardwareInterface>VelocityJointInterface</hardwareInterface>
  </actuator>
</transmission>
<transmission name="front_left_wheel_transmission">
  <type>transmission_interface/SimpleTransmission</type>
  <joint name="base_link_front_left_wheel_joint">
    <hardwareInterface>hardware_interface/VelocityJointInterface</hardwareInterface>
  </joint>
  <actuator name="front_left_wheel_actuator">
    <mechanicalReduction>7</mechanicalReduction>
    <hardwareInterface>VelocityJointInterface</hardwareInterface>
  </actuator>
</transmission>
<transmission name="front_right_wheel_transmission">
  <type>transmission_interface/SimpleTransmission</type>
  <joint name="base_link_front_right_wheel_joint">
    <hardwareInterface>hardware_interface/VelocityJointInterface</hardwareInterface>
  </joint>
  <actuator name="front_right_wheel_actuator">
    <mechanicalReduction>7</mechanicalReduction>
    <hardwareInterface>VelocityJointInterface</hardwareInterface>
  </actuator>
</transmission>
<transmission name="head_pan_joint_tran">
  <type>transmission_interface/SimpleTransmission</type>
  <joint name="chest_box_head_pan_joint">
    <hardwareInterface>hardware_interface/EffortJointInterface</hardwareInterface>
  </joint>
  <actuator name="head_pan_joint_motor">
    <hardwareInterface>hardware_interface/EffortJointInterface</hardwareInterface>
    <mechanicalReduction>1</mechanicalReduction>
  </actuator>
</transmission>
<transmission name="head_tilt_joint_tran">
  <type>transmission_interface/SimpleTransmission</type>
  <joint name="head_pan_head_tilt_joint">
    <hardwareInterface>hardware_interface/EffortJointInterface</hardwareInterface>
  </joint>
  <actuator name="head_tilt_joint_motor">
    <hardwareInterface>hardware_interface/EffortJointInterface</hardwareInterface>
    <mechanicalReduction>1</mechanicalReduction>
  </actuator>
</transmission>
<transmission name="right_arm_right_shoulder_tilt_joint_tran">
  <type>transmission_interface/SimpleTransmission</type>
  <joint name="right_arm_right_shoulder_tilt_joint">
    <hardwareInterface>hardware_interface/EffortJointInterface</hardwareInterface>
  </joint>
  <actuator name="right_arm_right_shoulder_tilt_joint_motor">
    <hardwareInterface>hardware_interface/EffortJointInterface</hardwareInterface>
    <mechanicalReduction>1</mechanicalReduction>
  </actuator>
</transmission>
<transmission name="right_shoulder_tilt_right_shoulder_pan_joint_tran">
  <type>transmission_interface/SimpleTransmission</type>
  <joint name="right_shoulder_tilt_right_shoulder_pan_joint">
    <hardwareInterface>hardware_interface/EffortJointInterface</hardwareInterface>
  </joint>
  <actuator name="right_shoulder_tilt_right_shoulder_pan_joint_motor">
    <hardwareInterface>hardware_interface/EffortJointInterface</hardwareInterface>
    <mechanicalReduction>1</mechanicalReduction>
  </actuator>
</transmission>
<transmission name="right_shoulder_pan_right_shoulder_rotate_joint_tran">
  <type>transmission_interface/SimpleTransmission</type>
  <joint name="right_shoulder_pan_right_shoulder_rotate_joint">
    <hardwareInterface>hardware_interface/EffortJointInterface</hardwareInterface>
  </joint>
  <actuator name="right_shoulder_pan_right_shoulder_rotate_joint_motor">
    <hardwareInterface>hardware_interface/EffortJointInterface</hardwareInterface>
    <mechanicalReduction>1</mechanicalReduction>
  </actuator>
</transmission>
<transmission name="right_shoulder_rotate_right_elbow_joint_tran">
  <type>transmission_interface/SimpleTransmission</type>
  <joint name="right_shoulder_rotate_right_elbow_joint">
    <hardwareInterface>hardware_interface/EffortJointInterface</hardwareInterface>
  </joint>
  <actuator name="right_shoulder_rotate_right_elbow_joint_motor">
    <hardwareInterface>hardware_interface/EffortJointInterface</hardwareInterface>
    <mechanicalReduction>1</mechanicalReduction>
  </actuator>
</transmission>
<transmission name="right_elbow_right_forearm_joint_tran">
  <type>transmission_interface/SimpleTransmission</type>
  <joint name="right_elbow_right_forearm_joint">
    <hardwareInterface>hardware_interface/EffortJointInterface</hardwareInterface>
  </joint>
  <actuator name="right_elbow_right_forearm_joint_motor">
    <hardwareInterface>hardware_interface/EffortJointInterface</hardwareInterface>
    <mechanicalReduction>1</mechanicalReduction>
  </actuator>
</transmission>
<transmission name="right_forearm_right_wrist_roll_joint_tran">
  <type>transmission_interface/SimpleTransmission</type>
  <joint name="right_forearm_right_wrist_roll_joint">
    <hardwareInterface>hardware_interface/EffortJointInterface</hardwareInterface>
  </joint>
  <actuator name="right_forearm_right_wrist_roll_joint_motor">
    <hardwareInterface>hardware_interface/EffortJointInterface</hardwareInterface>
    <mechanicalReduction>1</mechanicalReduction>
  </actuator>
</transmission>
<transmission name="right_wrist_roll_right_wrist_tilt_joint_tran">
  <type>transmission_interface/SimpleTransmission</type>
  <joint name="right_wrist_roll_right_wrist_tilt_joint">
    <hardwareInterface>hardware_interface/EffortJointInterface</hardwareInterface>
  </joint>
  <actuator name="right_wrist_roll_right_wrist_tilt_joint_motor">
    <hardwareInterface>hardware_interface/EffortJointInterface</hardwareInterface>
    <mechanicalReduction>1</mechanicalReduction>
  </actuator>
</transmission>
<transmission name="right_wrist_tilt_right_wrist_pan_joint_tran">
  <type>transmission_interface/SimpleTransmission</type>
  <joint name="right_wrist_tilt_right_wrist_pan_joint">
    <hardwareInterface>hardware_interface/EffortJointInterface</hardwareInterface>
  </joint>
  <actuator name="right_wrist_tilt_right_wrist_pan_joint_motor">
    <hardwareInterface>hardware_interface/EffortJointInterface</hardwareInterface>
    <mechanicalReduction>1</mechanicalReduction>
  </actuator>
</transmission>
<transmission name="left_arm_left_shoulder_tilt_joint_tran">
  <type>transmission_interface/SimpleTransmission</type>
  <joint name="left_arm_left_shoulder_tilt_joint">
    <hardwareInterface>hardware_interface/EffortJointInterface</hardwareInterface>
  </joint>
  <actuator name="left_arm_left_shoulder_tilt_joint_motor">
    <hardwareInterface>hardware_interface/EffortJointInterface</hardwareInterface>
    <mechanicalReduction>1</mechanicalReduction>
  </actuator>
</transmission>
<transmission name="left_shoulder_tilt_left_shoulder_pan_joint_tran">
  <type>transmission_interface/SimpleTransmission</type>
  <joint name="left_shoulder_tilt_left_shoulder_pan_joint">
    <hardwareInterface>hardware_interface/EffortJointInterface</hardwareInterface>
  </joint>
  <actuator name="left_shoulder_tilt_left_shoulder_pan_joint_motor">
    <hardwareInterface>hardware_interface/EffortJointInterface</hardwareInterface>
    <mechanicalReduction>1</mechanicalReduction>
  </actuator>
</transmission>
<transmission name="left_shoulder_pan_left_shoulder_rotate_joint_tran">
  <type>transmission_interface/SimpleTransmission</type>
  <joint name="left_shoulder_pan_left_shoulder_rotate_joint">
    <hardwareInterface>hardware_interface/EffortJointInterface</hardwareInterface>
  </joint>
  <actuator name="left_shoulder_pan_left_shoulder_rotate_joint_motor">
    <hardwareInterface>hardware_interface/EffortJointInterface</hardwareInterface>
    <mechanicalReduction>1</mechanicalReduction>
  </actuator>
</transmission>
<transmission name="left_shoulder_rotate_left_elbow_joint_tran">
  <type>transmission_interface/SimpleTransmission</type>
  <joint name="left_shoulder_rotate_left_elbow_joint">
    <hardwareInterface>hardware_interface/EffortJointInterface</hardwareInterface>
  </joint>
  <actuator name="left_shoulder_rotate_left_elbow_joint_motor">
    <hardwareInterface>hardware_interface/EffortJointInterface</hardwareInterface>
    <mechanicalReduction>1</mechanicalReduction>
  </actuator>
</transmission>
<transmission name="left_elbow_left_forearm_joint_tran">
  <type>transmission_interface/SimpleTransmission</type>
  <joint name="left_elbow_left_forearm_joint">
    <hardwareInterface>hardware_interface/EffortJointInterface</hardwareInterface>
  </joint>
  <actuator name="left_elbow_left_forearm_joint_motor">
    <hardwareInterface>hardware_interface/EffortJointInterface</hardwareInterface>
    <mechanicalReduction>1</mechanicalReduction>
  </actuator>
</transmission>
<transmission name="left_forearm_left_wrist_roll_joint_tran">
  <type>transmission_interface/SimpleTransmission</type>
  <joint name="left_forearm_left_wrist_roll_joint">
    <hardwareInterface>hardware_interface/EffortJointInterface</hardwareInterface>
  </joint>
  <actuator name="left_forearm_left_wrist_roll_joint_motor">
    <hardwareInterface>hardware_interface/EffortJointInterface</hardwareInterface>
    <mechanicalReduction>1</mechanicalReduction>
  </actuator>
</transmission>
<transmission name="left_wrist_roll_left_wrist_tilt_joint_tran">
  <type>transmission_interface/SimpleTransmission</type>
  <joint name="left_wrist_roll_left_wrist_tilt_joint">
    <hardwareInterface>hardware_interface/EffortJointInterface</hardwareInterface>
  </joint>
  <actuator name="left_wrist_roll_left_wrist_tilt_joint_motor">
    <hardwareInterface>hardware_interface/EffortJointInterface</hardwareInterface>
    <mechanicalReduction>1</mechanicalReduction>
  </actuator>
</transmission>
<transmission name="left_wrist_tilt_left_wrist_pan_joint_tran">
  <type>transmission_interface/SimpleTransmission</type>
  <joint name="left_wrist_tilt_left_wrist_pan_joint">
    <hardwareInterface>hardware_interface/EffortJointInterface</hardwareInterface>
  </joint>
  <actuator name="left_wrist_tilt_left_wrist_pan_joint_motor">
    <hardwareInterface>hardware_interface/EffortJointInterface</hardwareInterface>
    <mechanicalReduction>1</mechanicalReduction>
  </actuator>
</transmission>
<gazebo reference="left_camera">
  <sensor type="camera" name="left_camera">
    <update_rate>15.0</update_rate>
    <camera name="left">
      <pose>0 0 0 0 0 0</pose>
      <horizontal_fov>1.3962634</horizontal_fov>
      <image>
        <width>320</width>
        <height>240</height>
        <format>R8G8B8</format>
      </image>
      <clip>
        <near>0.01</near>
        <far>100</far>
      </clip>
      <noise>
        <type>gaussian</type>
        <stddev>0.007</stddev>
      </noise>
    </camera>
    <plugin name="camera_controller" filename="libgazebo_ros_camera.so">
      <alwaysOn>true</alwaysOn>
      <updateRate>0.0</updateRate>
      <cameraName>nefive/leftcamera</cameraName>
      <imageTopicName>image_raw</imageTopicName>
      <cameraInfoTopicName>camera_info</cameraInfoTopicName>
      <frameName>left_camera</frameName>
      <hackBaseline>0.07</hackBaseline>
      <distortionK1>0.0</distortionK1>
      <distortionK2>0.0</distortionK2>
      <distortionK3>0.0</distortionK3>
      <distortionT1>0.0</distortionT1>
      <distortionT2>0.0</distortionT2>
    </plugin>
  </sensor>
</gazebo>
<gazebo reference="right_camera">
  <sensor type="camera" name="right_camera">
    <update_rate>15.0</update_rate>
    <camera name="right">
      <pose>0 0 0 0 0 0</pose>
      <horizontal_fov>1.3962634</horizontal_fov>
      <image>
        <width>320</width>
        <height>240</height>
        <format>R8G8B8</format>
      </image>
      <clip>
        <near>0.01</near>
        <far>100</far>
      </clip>
      <noise>
        <type>gaussian</type>
        <stddev>0.007</stddev>
      </noise>
    </camera>
    <plugin name="camera_controller" filename="libgazebo_ros_camera.so">
      <alwaysOn>true</alwaysOn>
      <updateRate>0.0</updateRate>
      <cameraName>nefive/rightcamera</cameraName>
      <imageTopicName>image_raw</imageTopicName>
      <cameraInfoTopicName>camera_info</cameraInfoTopicName>
      <frameName>right_camera</frameName>
      <hackBaseline>0.07</hackBaseline>
      <distortionK1>0.0</distortionK1>
      <distortionK2>0.0</distortionK2>
      <distortionK3>0.0</distortionK3>
      <distortionT1>0.0</distortionT1>
      <distortionT2>0.0</distortionT2>
    </plugin>
  </sensor>
</gazebo>
</robot>